<?xml version="1.0" ?>
<!-- =================================================================================== -->
<!-- |    This document was autogenerated by xacro from reemc_full.urdf.xacro          | -->
<!-- |    EDITING THIS FILE BY HAND IS NOT RECOMMENDED                                 | -->
<!-- =================================================================================== -->
<!--

  Copyright (c) 2014, PAL Robotics, S.L.
  All rights reserved.

  This work is licensed under the Creative Commons Attribution-NonCommercial-NoDerivs 3.0 Unported License.
  To view a copy of this license, visit http://creativecommons.org/licenses/by-nc-nd/3.0/ or send a letter to
  Creative Commons, 444 Castro Street, Suite 900, Mountain View, California, 94041, USA.
-->
<robot name="reemc" xmlns:controller="http://playerstage.sourceforge.net/gazebo/xmlschema/#controller" xmlns:interface="http://playerstage.sourceforge.net/gazebo/xmlschema/#interface" xmlns:sensor="http://playerstage.sourceforge.net/gazebo/xmlschema/#sensor" xmlns:xacro="http://ros.org/wiki/xacro">
  <link name="base_link">
    <inertial>
      <mass value="12.3221"/>
      <origin rpy="0 0 0" xyz="-0.01209 -0.00442 0.02145"/>
      <inertia ixx="0.03408839175" ixy="0.00000898087" ixz="0.00238269732" iyy="0.03351929137" iyz="0.00049460232" izz="0.04506059363"/>
    </inertial>
    <visual>
      <origin rpy="0 0 0" xyz="0 0 0"/>
      <geometry>
        <mesh filename="package://reemc_description/meshes/base/base.dae"/>
      </geometry>
      <material name="LightGrey"/>
    </visual>
    <collision>
      <origin rpy="0 0 0" xyz="-0.022 0 0.01"/>
      <geometry>
        <box size="0.3 0.35 0.14"/>
      </geometry>
    </collision>
  </link>
  <!-- The following included files set up definitions of parts of the robot body -->
  <!--File includes-->
  <!--Constant parameters-->
  <!-- Torso -->
  <!--File includes-->
  <!--Constant parameters-->
  <!-- Head -->
  <!--File includes-->
  <!--Constant parameters-->
  <!--************************-->
  <!--     HEAD_1 (PAN)       -->
  <!--************************-->
  <!--************************-->
  <!--      HEAD_2 (TILT)     -->
  <!--************************-->
  <!-- Arm -->
  <!--File includes-->
  <!--File includes-->
  <!--Constant parameters-->
  <!-- TODO: Update dynamic models -->
  <!--Constant parameters-->
  <!-- TODO: Update dynamic models -->
  <!-- Hand -->
  <!--File includes-->
  <!-- Thumb -->
  <!-- Other fingers -->
  <!-- TODO: Implement as a single underactuated custom transmission for the whole finger -->
  <!--Constant parameters-->
  <!--TODO: Tune-->
  <!--TODO: Tune-->
  <!-- Sensors -->
  <!-- stereo baseline according to base_link which has X pointing forward, Y leftwards and Z upwards (required by Gazebo for a camera sensor) -->
  <!-- this macro is used for creating wide and narrow double stereo camera links -->
  <!-- back camera macro uses stingrayf033c_camera macros -->
  <!-- this macro is used for creating wide and narrow double back camera links -->
  <!-- Generic simulator_gazebo plugins -->
  <gazebo>
    <plugin filename="libgazebo_ros_control.so" name="gazebo_ros_control">
      <ns/>
      <robotSimType>reemc_hardware_gazebo/ReemcHardwareGazebo</robotSimType>
      <robotNamespace/>
      <controlPeriod>0.001</controlPeriod>
    </plugin>
    <plugin filename="libgazebo_ros_p3d.so" name="gazebo_ros_p3d">
      <bodyName>base_link</bodyName>
      <topicName>ground_truth_odom</topicName>
      <alwaysOn>true</alwaysOn>
      <updateRate>100.0</updateRate>
    </plugin>
  </gazebo>
  <gazebo>
    <plugin filename="libgazebo_ros_force.so" name="gazebo_ros_force">
      <bodyName>base_link</bodyName>
      <topicName>base_link_wrench</topicName>
    </plugin>
  </gazebo>
  <gazebo reference="imu_link">
    <!-- this is expected to be reparented to pelvis with appropriate offset
         when imu_link is reduced by fixed joint reduction -->
    <!-- todo: this is working with gazebo 1.4, need to write a unit test -->
    <sensor name="imu_sensor" type="imu">
      <always_on>1</always_on>
      <update_rate>1000.0</update_rate>
      <imu>
        <noise>
          <type>gaussian</type>
          <!-- Noise parameters from Boston Dynamics
               (http://gazebosim.org/wiki/Sensor_noise):
                 rates (rad/s): mean=0, stddev=2e-4
                 accels (m/s/s): mean=0, stddev=1.7e-2
                 rate bias (rad/s): 5e-6 - 1e-5
                 accel bias (m/s/s): 1e-1
               Experimentally, simulation provide rates with noise of
               about 1e-3 rad/s and accels with noise of about 1e-1 m/s/s.
               So we don't expect to see the noise unless number of inner iterations
               are increased.

               We will add bias.  In this model, bias is sampled once for rates
               and once for accels at startup; the sign (negative or positive)
               of each bias is then switched with equal probability.  Thereafter,
               the biases are fixed additive offsets.  We choose
               bias means and stddevs to produce biases close to the provided
               data. -->
          <rate>
            <mean>0.0</mean>
            <stddev>2e-4</stddev>
            <bias_mean>0.0000075</bias_mean>
            <bias_stddev>0.0000008</bias_stddev>
          </rate>
          <accel>
            <mean>0.0</mean>
            <stddev>1.7e-2</stddev>
            <bias_mean>0.1</bias_mean>
            <bias_stddev>0.001</bias_stddev>
          </accel>
        </noise>
      </imu>
    </sensor>
  </gazebo>
  <gazebo reference="r_foot">
    <mu1>0.9</mu1>
    <mu2>0.9</mu2>
    <fdir1>1 0 0</fdir1>
    <maxVel>1.0</maxVel>
    <minDepth>0.003</minDepth>
  </gazebo>
  <gazebo reference="l_foot">
    <mu1>0.9</mu1>
    <mu2>0.9</mu2>
    <fdir1>1 0 0</fdir1>
    <maxVel>1.0</maxVel>
    <minDepth>0.003</minDepth>
  </gazebo>
  <!-- define global properties -->
  <!-- Materials for visualization -->
  <material name="Blue">
    <color rgba="0.0 0.0 0.8 1.0"/>
  </material>
  <material name="Green">
    <color rgba="0.0 0.8 0.0 1.0"/>
  </material>
  <material name="Grey">
    <color rgba="0.7 0.7 0.7 1.0"/>
  </material>
  <material name="LightGrey">
    <color rgba="0.9 0.9 0.9 1.0"/>
  </material>
  <material name="DarkGrey">
    <color rgba="0.2 0.2 0.2 1.0"/>
  </material>
  <material name="Red">
    <color rgba="0.8 0.0 0.0 1.0"/>
  </material>
  <material name="White">
    <color rgba="1.0 1.0 1.0 1.0"/>
  </material>
  <!-- Now we can start using the macros included above to define the actual robot -->
  <!-- The reflect parameter takes the value 1 or -1 to respectively distinguish right from left side in expressions -->
  <link name="leg_right_1_link">
    <inertial>
      <mass value="1.02901"/>
      <origin rpy="0 0 0" xyz="-0.02571 0 0.02557"/>
      <inertia ixx="0.00132187534" ixy="0.00000001514" ixz="0.00040022268" iyy="0.0018528617" iyz="0.00000050713" izz="0.00084231334"/>
    </inertial>
    <visual>
      <origin rpy="0 0 0" xyz="0 0 0"/>
      <geometry>
        <mesh filename="package://reemc_description/meshes/leg/leg_1.dae" scale="1 1 1"/>
      </geometry>
      <material name="LightGrey"/>
    </visual>
  </link>
  <joint name="leg_right_1_joint" type="revolute">
    <origin rpy="0 0 0" xyz="0  -0.075 -0.14353"/>
    <axis xyz="0 0 1"/>
    <parent link="base_link"/>
    <child link="leg_right_1_link"/>
    <dynamics damping="1.0" friction="1.0"/>
    <limit effort="42.7" lower="-0.523598775598" upper="0.785398163397" velocity="2.35"/>
    <safety_controller k_position="100" k_velocity="100" soft_lower_limit="-0.523598775598" soft_upper_limit="0.785398163397"/>
  </joint>
  <link name="leg_right_2_link">
    <inertial>
      <mass value="0.69621"/>
      <origin rpy="0.0 0.0 0.0" xyz="0.00057 -0.00881 -0.01125"/>
      <inertia ixx="0.0008416476" ixy="-0.00000268743" ixz="0.00000667199" iyy="0.00039794844" iyz="0.00002668971" izz="0.00084196694"/>
    </inertial>
    <visual>
      <origin rpy="1.57079632679 0 0" xyz="0 0 0"/>
      <geometry>
        <cylinder length="0.10" radius="0.04"/>
      </geometry>
      <material name="LightGrey"/>
    </visual>
  </link>
  <joint name="leg_right_2_joint" type="revolute">
    <origin rpy="0 1.57079632679 0" xyz="0 0 0.0"/>
    <axis xyz="0 0 1"/>
    <parent link="leg_right_1_link"/>
    <child link="leg_right_2_link"/>
    <dynamics damping="1.0" friction="1.0"/>
    <limit effort="64.0" lower="-0.523598775598" upper="0.261799387799" velocity="2.27"/>
    <safety_controller k_position="100" k_velocity="100" soft_lower_limit="-0.523598775598" soft_upper_limit="0.261799387799"/>
  </joint>
  <link name="leg_right_3_link">
    <inertial>
      <mass value="3.97852"/>
      <origin rpy="0.0 0 0.0" xyz="0.14784 -0.01646 -0.01793"/>
      <inertia ixx="0.00507885174" ixy="-0.00034076421" ixz="-0.00225952731" iyy="0.02850097402" iyz="0.00003047874" izz="0.02632392239"/>
    </inertial>
    <visual>
      <origin rpy="0 0 0" xyz="0 0 0"/>
      <geometry>
        <mesh filename="package://reemc_description/meshes/leg/leg_3.dae" scale="1 1 -1.0"/>
      </geometry>
      <material name="LightGrey"/>
    </visual>
    <collision>
      <origin rpy="0 1.57079632679 0" xyz="0.15 0 -0.015"/>
      <geometry>
        <box size="0.15 0.10 0.20"/>
      </geometry>
    </collision>
  </link>
  <joint name="leg_right_3_joint" type="revolute">
    <origin rpy="-1.57079632679 0 0" xyz="0 0 0.0"/>
    <axis xyz="0 0 1"/>
    <parent link="leg_right_2_link"/>
    <child link="leg_right_3_link"/>
    <dynamics damping="1.0" friction="1.0"/>
    <limit effort="55.7" lower="-1.74532925199" upper="0.785398163397" velocity="3.64"/>
    <safety_controller k_position="100" k_velocity="100" soft_lower_limit="-1.74532925199" soft_upper_limit="0.785398163397"/>
  </joint>
  <link name="leg_right_4_link">
    <inertial>
      <mass value="2.86055"/>
      <origin rpy="0.0 0.0 0.0" xyz="0.14618 -0.0022 -0.02189"/>
      <inertia ixx="0.00361006492" ixy="0.00012218208" ixz="0.00160208242" iyy="0.02470649045" iyz="0.00008129755" izz="0.02272322206"/>
    </inertial>
    <visual>
      <origin rpy="0 0 0" xyz="0 0 0"/>
      <geometry>
        <mesh filename="package://reemc_description/meshes/leg/leg_4.dae" scale="1 1 -1.0"/>
      </geometry>
      <material name="LightGrey"/>
    </visual>
    <collision>
      <origin rpy="0 -1.57079632679 0" xyz="0.15 0 -0.015"/>
      <geometry>
        <box size="0.15 0.10 0.20"/>
      </geometry>
    </collision>
  </link>
  <joint name="leg_right_4_joint" type="revolute">
    <origin rpy="0 0 0" xyz="0.300 0 0.0"/>
    <axis xyz="0 0 1"/>
    <parent link="leg_right_3_link"/>
    <child link="leg_right_4_link"/>
    <dynamics damping="0.1" friction="0"/>
    <dynamics damping="1.0" friction="1.0"/>
    <limit effort="138.3" lower="0.0" upper="2.61799387799" velocity="3.225"/>
    <safety_controller k_position="100" k_velocity="100" soft_lower_limit="0.0" soft_upper_limit="2.61799387799"/>
  </joint>
  <link name="leg_right_5_link">
    <inertial>
      <mass value="0.68213"/>
      <origin rpy="0.0 0.0 0.0" xyz="-0.00028 0.01119 -0.00859"/>
      <inertia ixx="0.00082035023" ixy="0.00000048534" ixz="0.00000226301" iyy="0.00082074105" iyz="-0.00002892247" izz="0.00037614067"/>
    </inertial>
    <visual>
      <origin rpy="0 0 0" xyz="0 0 0"/>
      <geometry>
        <cylinder length="0.104" radius="0.04"/>
      </geometry>
      <material name="LightGrey"/>
    </visual>
  </link>
  <joint name="leg_right_5_joint" type="revolute">
    <origin rpy="0 0 0" xyz="0.30 0 0.0"/>
    <axis xyz="0 0 1"/>
    <parent link="leg_right_4_link"/>
    <child link="leg_right_5_link"/>
    <dynamics damping="1.0" friction="1.0"/>
    <limit effort="80.9" lower="-1.74532925199" upper="0.785398163397" velocity="2.44"/>
    <safety_controller k_position="100" k_velocity="100" soft_lower_limit="-1.74532925199" soft_upper_limit="0.785398163397"/>
  </joint>
  <link name="leg_right_6_link">
    <inertial>
      <mass value="2.00843"/>
      <origin rpy="0.0 0.0 0.0" xyz="0.06111 -0.00336 -0.00497"/>
      <inertia ixx="0.00366502559" ixy="0.00020479295" ixz="0.00112439297" iyy="0.00532618026" iyz="0.00012133755" izz="0.00353091463"/>
    </inertial>
    <visual>
      <origin rpy="0 0 0" xyz="0 0 0"/>
      <geometry>
        <mesh filename="package://reemc_description/meshes/leg/leg_6.dae" scale="1 -1.0 1"/>
      </geometry>
      <material name="LightGrey"/>
    </visual>
    <collision>
      <origin rpy="0 0 0" xyz="0.1 -0.01 0.025 "/>
      <geometry>
        <box size="0.02 0.14 0.210"/>
      </geometry>
    </collision>
  </link>
  <joint name="leg_right_6_joint" type="revolute">
    <origin rpy="1.57079632679 0 0" xyz="0 0 0"/>
    <axis xyz="0 0 1"/>
    <parent link="leg_right_5_link"/>
    <child link="leg_right_6_link"/>
    <dynamics damping="1.0" friction="1.0"/>
    <limit effort="64.0" lower="-0.261799387799" upper="0.523598775598" velocity="2.27"/>
    <safety_controller k_position="100" k_velocity="100" soft_lower_limit="-0.261799387799" soft_upper_limit="0.523598775598"/>
  </joint>
  <link name="right_sole_link">
    <inertial>
      <mass value="0.001"/>
      <origin rpy="0 0 0" xyz="0 0 0"/>
      <inertia ixx="0.0" ixy="0.0" ixz="0.0" iyy="0.0" iyz="0.0" izz="0.0"/>
    </inertial>
  </link>
  <joint name="right_sole_joint" type="fixed">
    <!-- origin x taken from link_${side}_6_link/visual/origin/x above -->
    <origin rpy="0.0 -1.57079632679 0.0" xyz="0.117 0.0 0.0"/>
    <axis xyz="0 0 1"/>
    <parent link="leg_right_6_link"/>
    <child link="right_sole_link"/>
    <dynamics damping="1.0" friction="1.0"/>
    <limit effort="60" lower="0.0" upper="0.0" velocity="0"/>
  </joint>
  <gazebo reference="leg_right_1_link">
    <mu1>0.9</mu1>
    <mu2>0.9</mu2>
  </gazebo>
  <gazebo reference="leg_right_2_link">
    <mu1>0.9</mu1>
    <mu2>0.9</mu2>
  </gazebo>
  <gazebo reference="leg_right_3_link">
    <mu1>0.9</mu1>
    <mu2>0.9</mu2>
  </gazebo>
  <gazebo reference="leg_right_4_link">
    <mu1>0.9</mu1>
    <mu2>0.9</mu2>
  </gazebo>
  <gazebo reference="leg_right_5_link">
    <mu1>0.9</mu1>
    <mu2>0.9</mu2>
  </gazebo>
  <!-- contact model for foot surface -->
  <gazebo reference="leg_right_6_link">
    <kp>1000000.0</kp>
    <kd>100.0</kd>
    <mu1>1.0</mu1>
    <mu2>1.0</mu2>
    <fdir1>0 0 1</fdir1>
    <maxVel>1.0</maxVel>
    <minDepth>0.00</minDepth>
    <implicitSpringDamper>1</implicitSpringDamper>
  </gazebo>
  <!--force torque sensor -->
  <!--xacro:reemc_force_torque_sensor name="leg_${side}_6_link"  update_rate="100.0"/-->
  <gazebo reference="leg_right_1_joint">
    <implicitSpringDamper>1</implicitSpringDamper>
  </gazebo>
  <gazebo reference="leg_right_2_joint">
    <implicitSpringDamper>1</implicitSpringDamper>
  </gazebo>
  <gazebo reference="leg_right_3_joint">
    <implicitSpringDamper>1</implicitSpringDamper>
  </gazebo>
  <gazebo reference="leg_right_4_joint">
    <implicitSpringDamper>1</implicitSpringDamper>
  </gazebo>
  <gazebo reference="leg_right_5_joint">
    <implicitSpringDamper>1</implicitSpringDamper>
  </gazebo>
  <gazebo reference="leg_right_6_joint">
    <implicitSpringDamper>1</implicitSpringDamper>
    <provideFeedback>1</provideFeedback>
  </gazebo>
  <transmission name="leg_right_1_trans">
    <type>transmission_interface/SimpleTransmission</type>
    <actuator name="leg_right_1_motor">
      <mechanicalReduction>1.0</mechanicalReduction>
    </actuator>
    <joint name="leg_right_1_joint">
      <hardwareInterface>hardware_interface/PositionJointInterface</hardwareInterface>
    </joint>
  </transmission>
  <transmission name="leg_right_2_trans">
    <type>transmission_interface/SimpleTransmission</type>
    <actuator name="leg_right_2_motor">
      <mechanicalReduction>1.0</mechanicalReduction>
    </actuator>
    <joint name="leg_right_2_joint">
      <hardwareInterface>hardware_interface/PositionJointInterface</hardwareInterface>
    </joint>
  </transmission>
  <transmission name="leg_right_3_trans">
    <type>transmission_interface/SimpleTransmission</type>
    <actuator name="leg_right_3_motor">
      <mechanicalReduction>1.0</mechanicalReduction>
    </actuator>
    <joint name="leg_right_3_joint">
      <hardwareInterface>hardware_interface/PositionJointInterface</hardwareInterface>
    </joint>
  </transmission>
  <transmission name="leg_right_4_trans">
    <type>transmission_interface/SimpleTransmission</type>
    <actuator name="leg_right_4_motor">
      <mechanicalReduction>1.0</mechanicalReduction>
    </actuator>
    <joint name="leg_right_4_joint">
      <hardwareInterface>hardware_interface/PositionJointInterface</hardwareInterface>
    </joint>
  </transmission>
  <transmission name="leg_right_5_trans">
    <type>transmission_interface/SimpleTransmission</type>
    <actuator name="leg_right_5_motor">
      <mechanicalReduction>1.0</mechanicalReduction>
    </actuator>
    <joint name="leg_right_5_joint">
      <hardwareInterface>hardware_interface/PositionJointInterface</hardwareInterface>
    </joint>
  </transmission>
  <transmission name="leg_right_6_trans">
    <type>transmission_interface/SimpleTransmission</type>
    <actuator name="leg_right_6_motor">
      <mechanicalReduction>1.0</mechanicalReduction>
    </actuator>
    <joint name="leg_right_6_joint">
      <hardwareInterface>hardware_interface/PositionJointInterface</hardwareInterface>
    </joint>
  </transmission>
  <link name="right_laser_link">
    <inertial>
      <origin rpy="0 0 0" xyz="0.0 0.0 0.0"/>
      <mass value="0.001"/>
      <inertia ixx="3.7174E-05" ixy="4.9927E-08" ixz="1.1015E-05" iyy="4.2412E-05" iyz="-9.8165E-09" izz="4.167E-05"/>
    </inertial>
    <!--    <visual>
         <origin xyz="0.0 0 0.05" rpy="0 0 ${90.0*deg_to_rad}" />
        <geometry>
          <mesh filename="package://reemc_description/meshes/sensors/urg-04lx-ug01.stl" scale="0.001 0.001 0.001"/>
        </geometry>
      <material name="DarkGrey" />
      </visual>
  -->
  </link>
  <joint name="right_laser_joint" type="fixed">
    <axis xyz="0 1 0"/>
    <origin rpy="0.0 0.0 -0.523598775598" xyz="0.085 -0.01 0.073"/>
    <parent link="right_sole_link"/>
    <child link="right_laser_link"/>
    <dynamics damping="1" friction="1.0"/>
    <limit effort="60" lower="0" upper="0" velocity="20"/>
  </joint>
  <!-- gazebo extensions -->
  <gazebo reference="right_laser_link">
    <sensor name="right_laser_sensor" type="ray">
      <pose>0 0 0 0 0 0</pose>
      <visualize>false</visualize>
      <update_rate>10.0</update_rate>
      <ray>
        <scan>
          <horizontal>
            <samples>360</samples>
            <resolution>1</resolution>
            <min_angle>-1.57079632679</min_angle>
            <max_angle>1.57079632679</max_angle>
          </horizontal>
        </scan>
        <range>
          <min>0.02</min>
          <max>5.6</max>
          <resolution>0.01</resolution>
        </range>
      </ray>
      <plugin filename="libgazebo_ros_laser.so" name="gazebo_ros_laser">
        <frameName>/right_laser_link</frameName>
        <topicName>right_scan</topicName>
        <gaussianNoise>0.03</gaussianNoise>
        <hokuyoMinIntensity>101</hokuyoMinIntensity>
        <updateRate>10.0</updateRate>
        <alwaysOn>true</alwaysOn>
      </plugin>
    </sensor>
  </gazebo>
  <link name="leg_left_1_link">
    <inertial>
      <mass value="1.02901"/>
      <origin rpy="0 0 0" xyz="-0.02571 0 0.02557"/>
      <inertia ixx="0.00132187534" ixy="0.00000001514" ixz="0.00040022268" iyy="0.0018528617" iyz="0.00000050713" izz="0.00084231334"/>
    </inertial>
    <visual>
      <origin rpy="0 0 0" xyz="0 0 0"/>
      <geometry>
        <mesh filename="package://reemc_description/meshes/leg/leg_1.dae" scale="1 1 1"/>
      </geometry>
      <material name="LightGrey"/>
    </visual>
  </link>
  <joint name="leg_left_1_joint" type="revolute">
    <origin rpy="0 0 0" xyz="0  0.075 -0.14353"/>
    <axis xyz="0 0 1"/>
    <parent link="base_link"/>
    <child link="leg_left_1_link"/>
    <dynamics damping="1.0" friction="1.0"/>
    <limit effort="42.7" lower="-0.785398163397" upper="0.523598775598" velocity="2.35"/>
    <safety_controller k_position="100" k_velocity="100" soft_lower_limit="-0.785398163397" soft_upper_limit="0.523598775598"/>
  </joint>
  <link name="leg_left_2_link">
    <inertial>
      <mass value="0.69621"/>
      <origin rpy="0.0 0.0 0.0" xyz="0.00057 0.00881 -0.01125"/>
      <inertia ixx="0.0008416476" ixy="-0.00000268743" ixz="0.00000667199" iyy="0.00039794844" iyz="0.00002668971" izz="0.00084196694"/>
    </inertial>
    <visual>
      <origin rpy="1.57079632679 0 0" xyz="0 0 0"/>
      <geometry>
        <cylinder length="0.10" radius="0.04"/>
      </geometry>
      <material name="LightGrey"/>
    </visual>
  </link>
  <joint name="leg_left_2_joint" type="revolute">
    <origin rpy="0 1.57079632679 0" xyz="0 0 0.0"/>
    <axis xyz="0 0 1"/>
    <parent link="leg_left_1_link"/>
    <child link="leg_left_2_link"/>
    <dynamics damping="1.0" friction="1.0"/>
    <limit effort="64.0" lower="-0.261799387799" upper="0.523598775598" velocity="2.27"/>
    <safety_controller k_position="100" k_velocity="100" soft_lower_limit="-0.261799387799" soft_upper_limit="0.523598775598"/>
  </joint>
  <link name="leg_left_3_link">
    <inertial>
      <mass value="3.97852"/>
      <origin rpy="0.0 0 0.0" xyz="0.14784 -0.01646 0.01793"/>
      <inertia ixx="0.00507885174" ixy="-0.00034076421" ixz="-0.00225952731" iyy="0.02850097402" iyz="0.00003047874" izz="0.02632392239"/>
    </inertial>
    <visual>
      <origin rpy="0 0 0" xyz="0 0 0"/>
      <geometry>
        <mesh filename="package://reemc_description/meshes/leg/leg_3.dae" scale="1 1 1.0"/>
      </geometry>
      <material name="LightGrey"/>
    </visual>
    <collision>
      <origin rpy="0 1.57079632679 0" xyz="0.15 0 0.015"/>
      <geometry>
        <box size="0.15 0.10 0.20"/>
      </geometry>
    </collision>
  </link>
  <joint name="leg_left_3_joint" type="revolute">
    <origin rpy="-1.57079632679 0 0" xyz="0 0 0.0"/>
    <axis xyz="0 0 1"/>
    <parent link="leg_left_2_link"/>
    <child link="leg_left_3_link"/>
    <dynamics damping="1.0" friction="1.0"/>
    <limit effort="55.7" lower="-1.74532925199" upper="0.785398163397" velocity="3.64"/>
    <safety_controller k_position="100" k_velocity="100" soft_lower_limit="-1.74532925199" soft_upper_limit="0.785398163397"/>
  </joint>
  <link name="leg_left_4_link">
    <inertial>
      <mass value="2.86055"/>
      <origin rpy="0.0 0.0 0.0" xyz="0.14618 -0.0022 0.02189"/>
      <inertia ixx="0.00361006492" ixy="0.00012218208" ixz="0.00160208242" iyy="0.02470649045" iyz="0.00008129755" izz="0.02272322206"/>
    </inertial>
    <visual>
      <origin rpy="0 0 0" xyz="0 0 0"/>
      <geometry>
        <mesh filename="package://reemc_description/meshes/leg/leg_4.dae" scale="1 1 1.0"/>
      </geometry>
      <material name="LightGrey"/>
    </visual>
    <collision>
      <origin rpy="0 1.57079632679 0" xyz="0.15 0 0.015"/>
      <geometry>
        <box size="0.15 0.10 0.20"/>
      </geometry>
    </collision>
  </link>
  <joint name="leg_left_4_joint" type="revolute">
    <origin rpy="0 0 0" xyz="0.300 0 0.0"/>
    <axis xyz="0 0 1"/>
    <parent link="leg_left_3_link"/>
    <child link="leg_left_4_link"/>
    <dynamics damping="0.1" friction="0"/>
    <dynamics damping="1.0" friction="1.0"/>
    <limit effort="138.3" lower="0.0" upper="2.61799387799" velocity="3.225"/>
    <safety_controller k_position="100" k_velocity="100" soft_lower_limit="0.0" soft_upper_limit="2.61799387799"/>
  </joint>
  <link name="leg_left_5_link">
    <inertial>
      <mass value="0.68213"/>
      <origin rpy="0.0 0.0 0.0" xyz="-0.00028 0.01119 0.00859"/>
      <inertia ixx="0.00082035023" ixy="0.00000048534" ixz="0.00000226301" iyy="0.00082074105" iyz="-0.00002892247" izz="0.00037614067"/>
    </inertial>
    <visual>
      <origin rpy="0 0 0" xyz="0 0 0"/>
      <geometry>
        <cylinder length="0.104" radius="0.04"/>
      </geometry>
      <material name="LightGrey"/>
    </visual>
  </link>
  <joint name="leg_left_5_joint" type="revolute">
    <origin rpy="0 0 0" xyz="0.30 0 0.0"/>
    <axis xyz="0 0 1"/>
    <parent link="leg_left_4_link"/>
    <child link="leg_left_5_link"/>
    <dynamics damping="1.0" friction="1.0"/>
    <limit effort="80.9" lower="-1.74532925199" upper="0.785398163397" velocity="2.44"/>
    <safety_controller k_position="100" k_velocity="100" soft_lower_limit="-1.74532925199" soft_upper_limit="0.785398163397"/>
  </joint>
  <link name="leg_left_6_link">
    <inertial>
      <mass value="2.00843"/>
      <origin rpy="0.0 0.0 0.0" xyz="0.06111 0.00336 -0.00497"/>
      <inertia ixx="0.00366502559" ixy="0.00020479295" ixz="0.00112439297" iyy="0.00532618026" iyz="0.00012133755" izz="0.00353091463"/>
    </inertial>
    <visual>
      <origin rpy="0 0 0" xyz="0 0 0"/>
      <geometry>
        <mesh filename="package://reemc_description/meshes/leg/leg_6.dae" scale="1 1.0 1"/>
      </geometry>
      <material name="LightGrey"/>
    </visual>
    <collision>
      <origin rpy="0 0 0" xyz="0.1 0.01 0.025 "/>
      <geometry>
        <box size="0.02 0.14 0.210"/>
      </geometry>
    </collision>
  </link>
  <joint name="leg_left_6_joint" type="revolute">
    <origin rpy="1.57079632679 0 0" xyz="0 0 0"/>
    <axis xyz="0 0 1"/>
    <parent link="leg_left_5_link"/>
    <child link="leg_left_6_link"/>
    <dynamics damping="1.0" friction="1.0"/>
    <limit effort="64.0" lower="-0.523598775598" upper="0.261799387799" velocity="2.27"/>
    <safety_controller k_position="100" k_velocity="100" soft_lower_limit="-0.523598775598" soft_upper_limit="0.261799387799"/>
  </joint>
  <link name="left_sole_link">
    <inertial>
      <mass value="0.001"/>
      <origin rpy="0 0 0" xyz="0 0 0"/>
      <inertia ixx="0.0" ixy="0.0" ixz="0.0" iyy="0.0" iyz="0.0" izz="0.0"/>
    </inertial>
  </link>
  <joint name="left_sole_joint" type="fixed">
    <!-- origin x taken from link_${side}_6_link/visual/origin/x above -->
    <origin rpy="0.0 -1.57079632679 0.0" xyz="0.117 0.0 0.0"/>
    <axis xyz="0 0 1"/>
    <parent link="leg_left_6_link"/>
    <child link="left_sole_link"/>
    <dynamics damping="1.0" friction="1.0"/>
    <limit effort="60" lower="0.0" upper="0.0" velocity="0"/>
  </joint>
  <gazebo reference="leg_left_1_link">
    <mu1>0.9</mu1>
    <mu2>0.9</mu2>
  </gazebo>
  <gazebo reference="leg_left_2_link">
    <mu1>0.9</mu1>
    <mu2>0.9</mu2>
  </gazebo>
  <gazebo reference="leg_left_3_link">
    <mu1>0.9</mu1>
    <mu2>0.9</mu2>
  </gazebo>
  <gazebo reference="leg_left_4_link">
    <mu1>0.9</mu1>
    <mu2>0.9</mu2>
  </gazebo>
  <gazebo reference="leg_left_5_link">
    <mu1>0.9</mu1>
    <mu2>0.9</mu2>
  </gazebo>
  <!-- contact model for foot surface -->
  <gazebo reference="leg_left_6_link">
    <kp>1000000.0</kp>
    <kd>100.0</kd>
    <mu1>1.0</mu1>
    <mu2>1.0</mu2>
    <fdir1>0 0 1</fdir1>
    <maxVel>1.0</maxVel>
    <minDepth>0.00</minDepth>
    <implicitSpringDamper>1</implicitSpringDamper>
  </gazebo>
  <!--force torque sensor -->
  <!--xacro:reemc_force_torque_sensor name="leg_${side}_6_link"  update_rate="100.0"/-->
  <gazebo reference="leg_left_1_joint">
    <implicitSpringDamper>1</implicitSpringDamper>
  </gazebo>
  <gazebo reference="leg_left_2_joint">
    <implicitSpringDamper>1</implicitSpringDamper>
  </gazebo>
  <gazebo reference="leg_left_3_joint">
    <implicitSpringDamper>1</implicitSpringDamper>
  </gazebo>
  <gazebo reference="leg_left_4_joint">
    <implicitSpringDamper>1</implicitSpringDamper>
  </gazebo>
  <gazebo reference="leg_left_5_joint">
    <implicitSpringDamper>1</implicitSpringDamper>
  </gazebo>
  <gazebo reference="leg_left_6_joint">
    <implicitSpringDamper>1</implicitSpringDamper>
    <provideFeedback>1</provideFeedback>
  </gazebo>
  <transmission name="leg_left_1_trans">
    <type>transmission_interface/SimpleTransmission</type>
    <actuator name="leg_left_1_motor">
      <mechanicalReduction>1.0</mechanicalReduction>
    </actuator>
    <joint name="leg_left_1_joint">
      <hardwareInterface>hardware_interface/PositionJointInterface</hardwareInterface>
    </joint>
  </transmission>
  <transmission name="leg_left_2_trans">
    <type>transmission_interface/SimpleTransmission</type>
    <actuator name="leg_left_2_motor">
      <mechanicalReduction>1.0</mechanicalReduction>
    </actuator>
    <joint name="leg_left_2_joint">
      <hardwareInterface>hardware_interface/PositionJointInterface</hardwareInterface>
    </joint>
  </transmission>
  <transmission name="leg_left_3_trans">
    <type>transmission_interface/SimpleTransmission</type>
    <actuator name="leg_left_3_motor">
      <mechanicalReduction>1.0</mechanicalReduction>
    </actuator>
    <joint name="leg_left_3_joint">
      <hardwareInterface>hardware_interface/PositionJointInterface</hardwareInterface>
    </joint>
  </transmission>
  <transmission name="leg_left_4_trans">
    <type>transmission_interface/SimpleTransmission</type>
    <actuator name="leg_left_4_motor">
      <mechanicalReduction>1.0</mechanicalReduction>
    </actuator>
    <joint name="leg_left_4_joint">
      <hardwareInterface>hardware_interface/PositionJointInterface</hardwareInterface>
    </joint>
  </transmission>
  <transmission name="leg_left_5_trans">
    <type>transmission_interface/SimpleTransmission</type>
    <actuator name="leg_left_5_motor">
      <mechanicalReduction>1.0</mechanicalReduction>
    </actuator>
    <joint name="leg_left_5_joint">
      <hardwareInterface>hardware_interface/PositionJointInterface</hardwareInterface>
    </joint>
  </transmission>
  <transmission name="leg_left_6_trans">
    <type>transmission_interface/SimpleTransmission</type>
    <actuator name="leg_left_6_motor">
      <mechanicalReduction>1.0</mechanicalReduction>
    </actuator>
    <joint name="leg_left_6_joint">
      <hardwareInterface>hardware_interface/PositionJointInterface</hardwareInterface>
    </joint>
  </transmission>
  <link name="left_laser_link">
    <inertial>
      <origin rpy="0 0 0" xyz="0.0 0.0 0.0"/>
      <mass value="0.001"/>
      <inertia ixx="3.7174E-05" ixy="4.9927E-08" ixz="1.1015E-05" iyy="4.2412E-05" iyz="-9.8165E-09" izz="4.167E-05"/>
    </inertial>
    <!--    <visual>
         <origin xyz="0.0 0 0.05" rpy="0 0 ${90.0*deg_to_rad}" />
        <geometry>
          <mesh filename="package://reemc_description/meshes/sensors/urg-04lx-ug01.stl" scale="0.001 0.001 0.001"/>
        </geometry>
      <material name="DarkGrey" />
      </visual>
  -->
  </link>
  <joint name="left_laser_joint" type="fixed">
    <axis xyz="0 1 0"/>
    <origin rpy="0.0 0.0 0.523598775598" xyz="0.085 0.01 0.073"/>
    <parent link="left_sole_link"/>
    <child link="left_laser_link"/>
    <dynamics damping="1" friction="1.0"/>
    <limit effort="60" lower="0" upper="0" velocity="20"/>
  </joint>
  <!-- gazebo extensions -->
  <gazebo reference="left_laser_link">
    <sensor name="left_laser_sensor" type="ray">
      <pose>0 0 0 0 0 0</pose>
      <visualize>false</visualize>
      <update_rate>10.0</update_rate>
      <ray>
        <scan>
          <horizontal>
            <samples>360</samples>
            <resolution>1</resolution>
            <min_angle>-1.57079632679</min_angle>
            <max_angle>1.57079632679</max_angle>
          </horizontal>
        </scan>
        <range>
          <min>0.02</min>
          <max>5.6</max>
          <resolution>0.01</resolution>
        </range>
      </ray>
      <plugin filename="libgazebo_ros_laser.so" name="gazebo_ros_laser">
        <frameName>/left_laser_link</frameName>
        <topicName>left_scan</topicName>
        <gaussianNoise>0.03</gaussianNoise>
        <hokuyoMinIntensity>101</hokuyoMinIntensity>
        <updateRate>10.0</updateRate>
        <alwaysOn>true</alwaysOn>
      </plugin>
    </sensor>
  </gazebo>
  <!--************************-->
  <!--        TORSO_1         -->
  <!--************************-->
  <link name="torso_1_link">
    <inertial>
      <origin rpy="0 0 0" xyz="-0.00011 -0.00002 -0.00669"/>
      <mass value="1.58341"/>
      <!-- NOTE: Assuming cylinder with length="0.295" radius="0.0465-->
      <inertia ixx="0.0036591855" ixy="0.00000036753" ixz="0.00000297759" iyy="0.00115955355" iyz="0.00000024742" izz="0.00360440105"/>
    </inertial>
    <visual>
      <origin rpy="1.57079632679 0 0" xyz="0 0 0"/>
      <geometry>
        <cylinder length="0.15" radius="0.0465"/>
      </geometry>
      <material name="DarkGrey"/>
    </visual>
  </link>
  <joint name="torso_1_joint" type="revolute">
    <parent link="base_link"/>
    <child link="torso_1_link"/>
    <origin rpy="0 0 0" xyz="0 0 0.14353"/>
    <axis xyz="0 0 1"/>
    <limit effort="78.0" lower="-1.308996939" upper="1.308996939" velocity="5.4"/>
    <dynamics damping="1.0" friction="1.0"/>
    <safety_controller k_position="20" k_velocity="20" soft_lower_limit="-1.288996939" soft_upper_limit="1.288996939"/>
  </joint>
  <!--************************-->
  <!--        TORSO_2         -->
  <!--************************-->
  <link name="torso_2_link">
    <inertial>
      <origin rpy="0 0 0" xyz="-0.01816 -0.17956 -0.00103"/>
      <mass value="11.18103"/>
      <!-- NOTE: Assuming box with d=0.2, w=0.295, h=0.254 -->
      <inertia ixx="0.159836691" ixy="-0.00377573015" ixz="0.00094280162" iyy="0.08484637595" iyz="0.00020220508" izz="0.13253975464"/>
    </inertial>
    <visual>
      <origin rpy="0 0 0" xyz="0 0 0"/>
      <geometry>
        <mesh filename="package://reemc_description/meshes/torso/torso_2.dae"/>
      </geometry>
      <material name="LightGrey"/>
    </visual>
    <collision>
      <origin rpy="0 0 0" xyz="0 0 0"/>
      <geometry>
        <mesh filename="package://reemc_description/meshes/torso/torso_2_collision.stl"/>
      </geometry>
    </collision>
  </link>
  <joint name="torso_2_joint" type="revolute">
    <parent link="torso_1_link"/>
    <child link="torso_2_link"/>
    <origin rpy="-1.57079632679 0 0" xyz="0 0 0"/>
    <axis xyz="0 0 1"/>
    <limit effort="78.0" lower="-0.261799387799" upper="0.785398163397" velocity="5.4"/>
    <dynamics damping="1.0" friction="1.0"/>
    <safety_controller k_position="20" k_velocity="20" soft_lower_limit="-0.241799387799" soft_upper_limit="0.765398163397"/>
  </joint>
  <gazebo reference="torso_1_link">
    <mu1>0.9</mu1>
    <mu2>0.9</mu2>
  </gazebo>
  <gazebo reference="torso_2_link">
    <mu1>0.9</mu1>
    <mu2>0.9</mu2>
  </gazebo>
  <gazebo reference="torso_1_joint">
    <implicitSpringDamper>1</implicitSpringDamper>
  </gazebo>
  <gazebo reference="torso_2_joint">
    <implicitSpringDamper>1</implicitSpringDamper>
    <provideFeedback>1</provideFeedback>
  </gazebo>
  <!-- Torso Front Sonar Ring -->
  <!-- torso sonar left -->
  <link name="torso_sonar_01_link">
    <inertial>
      <mass value="0.001"/>
      <origin rpy="0 0 0" xyz="0 0 0"/>
      <inertia ixx="0.0001" ixy="0" ixz="0" iyy="0.000001" iyz="0" izz="0.0001"/>
    </inertial>
  </link>
  <joint name="torso_sonar_01_joint" type="fixed">
    <origin rpy="0.0 0.0 0.349065850399" xyz="0.10 -0.029 0"/>
    <axis xyz="0 0 1"/>
    <parent link="torso_2_link"/>
    <child link="torso_sonar_01_link"/>
  </joint>
  <!-- gazebo extensions -->
  <gazebo reference="torso_sonar_01_link">
    <sensor name="torso_sonar_01" type="ray">
      <pose>0 0 0 0 0 0</pose>
      <update_rate>5</update_rate>
      <visualize>false</visualize>
      <ray>
        <scan>
          <horizontal>
            <samples>5</samples>
            <resolution>1</resolution>
            <min_angle>-0.17455</min_angle>
            <max_angle>0.17455</max_angle>
          </horizontal>
          <vertical>
            <samples>5</samples>
            <resolution>1</resolution>
            <min_angle>-0.17455</min_angle>
            <max_angle>0.17455</max_angle>
          </vertical>
        </scan>
        <range>
          <min>0.005</min>
          <max>0.7</max>
          <resolution>0.01</resolution>
        </range>
      </ray>
      <plugin filename="libgazebo_ros_range.so" name="gazebo_ros_range">
        <gaussianNoise>0.005</gaussianNoise>
        <alwaysOn>true</alwaysOn>
        <updateRate>5</updateRate>
        <topicName>sonar_torso</topicName>
        <frameName>torso_sonar_01_link</frameName>
        <minRange>0.005</minRange>
        <maxRange>0.7</maxRange>
        <fov>0.3491</fov>
        <radiation>ultrasound</radiation>
      </plugin>
    </sensor>
  </gazebo>
  <!-- torso sonar right -->
  <link name="torso_sonar_02_link">
    <inertial>
      <mass value="0.001"/>
      <origin rpy="0 0 0" xyz="0 0 0"/>
      <inertia ixx="0.0001" ixy="0" ixz="0" iyy="0.000001" iyz="0" izz="0.0001"/>
    </inertial>
  </link>
  <joint name="torso_sonar_02_joint" type="fixed">
    <origin rpy="0.0 0.0 0.0" xyz="0.15 -0.18 0"/>
    <axis xyz="0 0 1"/>
    <parent link="torso_2_link"/>
    <child link="torso_sonar_02_link"/>
  </joint>
  <!-- gazebo extensions -->
  <gazebo reference="torso_sonar_02_link">
    <sensor name="torso_sonar_02" type="ray">
      <pose>0 0 0 0 0 0</pose>
      <update_rate>5</update_rate>
      <visualize>false</visualize>
      <ray>
        <scan>
          <horizontal>
            <samples>5</samples>
            <resolution>1</resolution>
            <min_angle>-0.17455</min_angle>
            <max_angle>0.17455</max_angle>
          </horizontal>
          <vertical>
            <samples>5</samples>
            <resolution>1</resolution>
            <min_angle>-0.17455</min_angle>
            <max_angle>0.17455</max_angle>
          </vertical>
        </scan>
        <range>
          <min>0.005</min>
          <max>0.7</max>
          <resolution>0.01</resolution>
        </range>
      </ray>
      <plugin filename="libgazebo_ros_range.so" name="gazebo_ros_range">
        <gaussianNoise>0.005</gaussianNoise>
        <alwaysOn>true</alwaysOn>
        <updateRate>5</updateRate>
        <topicName>sonar_torso</topicName>
        <frameName>torso_sonar_02_link</frameName>
        <minRange>0.005</minRange>
        <maxRange>0.7</maxRange>
        <fov>0.3491</fov>
        <radiation>ultrasound</radiation>
      </plugin>
    </sensor>
  </gazebo>
  <!-- torso sonar back -->
  <link name="torso_sonar_04_link">
    <inertial>
      <mass value="0.001"/>
      <origin rpy="0 0 0" xyz="0 0 0"/>
      <inertia ixx="0.0001" ixy="0" ixz="0" iyy="0.000001" iyz="0" izz="0.0001"/>
    </inertial>
  </link>
  <joint name="torso_sonar_04_joint" type="fixed">
    <origin rpy="0.0 3.14159265359 0.0" xyz="-0.17 -0.029 0.0"/>
    <axis xyz="0 0 1"/>
    <parent link="torso_2_link"/>
    <child link="torso_sonar_04_link"/>
  </joint>
  <!-- gazebo extensions -->
  <gazebo reference="torso_sonar_04_link">
    <sensor name="torso_sonar_04" type="ray">
      <pose>0 0 0 0 0 0</pose>
      <update_rate>5</update_rate>
      <visualize>false</visualize>
      <ray>
        <scan>
          <horizontal>
            <samples>5</samples>
            <resolution>1</resolution>
            <min_angle>-0.17455</min_angle>
            <max_angle>0.17455</max_angle>
          </horizontal>
          <vertical>
            <samples>5</samples>
            <resolution>1</resolution>
            <min_angle>-0.17455</min_angle>
            <max_angle>0.17455</max_angle>
          </vertical>
        </scan>
        <range>
          <min>0.005</min>
          <max>0.7</max>
          <resolution>0.01</resolution>
        </range>
      </ray>
      <plugin filename="libgazebo_ros_range.so" name="gazebo_ros_range">
        <gaussianNoise>0.005</gaussianNoise>
        <alwaysOn>true</alwaysOn>
        <updateRate>5</updateRate>
        <topicName>sonar_torso</topicName>
        <frameName>torso_sonar_04_link</frameName>
        <minRange>0.005</minRange>
        <maxRange>0.7</maxRange>
        <fov>0.3491</fov>
        <radiation>ultrasound</radiation>
      </plugin>
    </sensor>
  </gazebo>
  <!-- extensions -->
  <transmission name="torso_trans">
    <type>transmission_interface/DifferentialTransmission</type>
    <actuator name="torso_1_motor">
      <role>actuator1</role>
      <mechanicalReduction>1.0</mechanicalReduction>
    </actuator>
    <actuator name="torso_2_motor">
      <role>actuator2</role>
      <mechanicalReduction>1.0</mechanicalReduction>
    </actuator>
    <joint name="torso_1_joint">
      <role>joint1</role>
      <offset>0.0</offset>
      <mechanicalReduction>1.0</mechanicalReduction>
      <hardwareInterface>hardware_interface/PositionJointInterface</hardwareInterface>
    </joint>
    <joint name="torso_2_joint">
      <role>joint2</role>
      <offset>0.0</offset>
      <mechanicalReduction>1.0</mechanicalReduction>
      <hardwareInterface>hardware_interface/PositionJointInterface</hardwareInterface>
    </joint>
  </transmission>
  <link name="head_1_link">
    <inertial>
      <origin rpy="0 0 0" xyz="0.01819 0.00248 -0.00517"/>
      <mass value="1.11967"/>
      <!-- NOTE: Assuming cylinder with r=0.06, h=0.08 -->
      <!--         <inertia ixx="0.0014125"  ixy="0"  ixz="0" iyy="0.0014125" iyz="0" izz="0.0017738" /> -->
      <inertia ixx="0.00111370229" ixy="0.00003992198" ixz="-0.00012464155" iyy="0.00111361487" iyz="0.00001943162" izz="0.00114794061"/>
    </inertial>
    <visual>
      <origin rpy="0 0 0" xyz="-0.03 0 0"/>
      <!--TODO: Remove offset when good meshes arrive-->
      <geometry>
        <mesh filename="package://reemc_description/meshes/head/head_1.dae"/>
      </geometry>
      <material name="DarkGrey"/>
    </visual>
    <collision>
      <origin rpy="0 0 0" xyz="-0.03 0 0"/>
      <geometry>
        <mesh filename="package://reemc_description/meshes/head/head_1_collision.stl"/>
      </geometry>
    </collision>
  </link>
  <joint name="head_1_joint" type="revolute">
    <parent link="torso_2_link"/>
    <child link="head_1_link"/>
    <origin rpy="1.57079632679 0 0" xyz="0.0 -0.42316 0"/>
    <axis xyz="0 0 1"/>
    <limit effort="3.4" lower="-1.308996939" upper="1.308996939" velocity="3.0"/>
    <dynamics damping="0.5" friction="1.0"/>
    <safety_controller k_position="20" k_velocity="20" soft_lower_limit="-1.288996939" soft_upper_limit="1.288996939"/>
  </joint>
  <gazebo reference="head_1_link">
    <mu1>0.9</mu1>
    <mu2>0.9</mu2>
  </gazebo>
  <gazebo reference="head_1_joint">
    <implicitSpringDamper>1</implicitSpringDamper>
  </gazebo>
  <!-- extensions -->
  <transmission name="head_1_trans">
    <type>transmission_interface/SimpleTransmission</type>
    <actuator name="head_1_motor">
      <mechanicalReduction>1</mechanicalReduction>
    </actuator>
    <joint name="head_1_joint">
      <hardwareInterface>hardware_interface/PositionJointInterface</hardwareInterface>
    </joint>
  </transmission>
  <link name="head_2_link">
    <inertial>
      <origin rpy="0 0 0" xyz="0.01183 -0.08098 0.00104"/>
      <mass value="1.63134"/>
      <!-- NOTE: Assuming box with d=0.28433, w=0.20302, h=0.26741 -->
      <!--         <inertia ixx="0.011353"  ixy="0"  ixz="0" iyy="0.012294" iyz="0" izz="0.015345" /> -->
      <!--NOTE: Low (0.1 or lower) diagonal inertia values make Gazebo 1.0.2 simulation unstable when head sensors are added.-->
      <inertia ixx="0.00640199093" ixy="0.00012197067" ixz="-0.00000897011" iyy="0.00676228591" iyz="-0.0000552329" izz="0.00614192438"/>
    </inertial>
    <visual>
      <origin rpy="0 0 0" xyz="-0.03 0 0"/>
      <!--TODO: Remove offset when good meshes arrive-->
      <geometry>
        <mesh filename="package://reemc_description/meshes/head/head_2.dae"/>
      </geometry>
      <material name="LightGrey"/>
    </visual>
    <collision>
      <origin rpy="0 0 0" xyz="-0.03 0 0"/>
      <geometry>
        <mesh filename="package://reemc_description/meshes/head/head_2_collision.stl"/>
      </geometry>
    </collision>
  </link>
  <joint name="head_2_joint" type="revolute">
    <parent link="head_1_link"/>
    <child link="head_2_link"/>
    <origin rpy="-1.57079632679 0 0" xyz="0.0445 0 0"/>
    <axis xyz="0 0 1"/>
    <limit effort="3.26" lower="-0.261799387799" upper="0.785398163397" velocity="3.0"/>
    <dynamics damping="0.5" friction="1.0"/>
    <safety_controller k_position="20" k_velocity="20" soft_lower_limit="-0.241799387799" soft_upper_limit="0.349065850399"/>
  </joint>
  <gazebo reference="head_2_link">
    <mu1>0.9</mu1>
    <mu2>0.9</mu2>
  </gazebo>
  <gazebo reference="head_2_joint">
    <implicitSpringDamper>1</implicitSpringDamper>
  </gazebo>
  <!-- Head Sonar -->
  <link name="head_sonar_03_link">
    <inertial>
      <mass value="0.001"/>
      <origin rpy="0 0 0" xyz="0 0 0"/>
      <inertia ixx="0.0001" ixy="0" ixz="0" iyy="0.000001" iyz="0" izz="0.0001"/>
    </inertial>
  </link>
  <joint name="head_sonar_03_joint" type="fixed">
    <origin rpy="1.57 0.0 0.0" xyz="0.11 -0.195 0.0"/>
    <axis xyz="0 0 1"/>
    <parent link="head_2_link"/>
    <child link="head_sonar_03_link"/>
  </joint>
  <!-- gazebo extensions -->
  <gazebo reference="head_sonar_03_link">
    <sensor name="head_sonar_03" type="ray">
      <pose>0 0 0 0 0 0</pose>
      <update_rate>5</update_rate>
      <visualize>false</visualize>
      <ray>
        <scan>
          <horizontal>
            <samples>5</samples>
            <resolution>1</resolution>
            <min_angle>-0.17455</min_angle>
            <max_angle>0.17455</max_angle>
          </horizontal>
          <vertical>
            <samples>5</samples>
            <resolution>1</resolution>
            <min_angle>-0.17455</min_angle>
            <max_angle>0.17455</max_angle>
          </vertical>
        </scan>
        <range>
          <min>0.0</min>
          <max>0.6</max>
          <resolution>0.01</resolution>
        </range>
      </ray>
      <plugin filename="libgazebo_ros_range.so" name="gazebo_ros_range">
        <gaussianNoise>0.005</gaussianNoise>
        <alwaysOn>true</alwaysOn>
        <updateRate>5</updateRate>
        <topicName>sonar_torso</topicName>
        <frameName>head_sonar_03_link</frameName>
        <minRange>0.0</minRange>
        <maxRange>0.6</maxRange>
        <fov>0.3491</fov>
        <radiation>ultrasound</radiation>
      </plugin>
    </sensor>
  </gazebo>
  <!-- extensions -->
  <transmission name="head_2_trans">
    <type>transmission_interface/SimpleTransmission</type>
    <actuator name="head_2_motor">
      <mechanicalReduction>1</mechanicalReduction>
    </actuator>
    <joint name="head_2_joint">
      <hardwareInterface>hardware_interface/PositionJointInterface</hardwareInterface>
    </joint>
  </transmission>
  <!--************************-->
  <!--        SHOULDER        -->
  <!--************************-->
  <link name="arm_right_1_link">
    <inertial>
      <origin rpy="0 0 0" xyz="0.00701 -0.00011 0.18627"/>
      <mass value="1.53614"/>
      <!--        <inertia ixx="0"  ixy="0"  ixz="0" iyy="0" iyz="0" izz="0" /> -->
      <!--         NOTE: Assuming cylinder centered at CoM with r=0.05, h=0.05 with axis parallel to x coordinate -->
      <!--        <inertia ixx="0.0026850"  ixy="0"  ixz="0" iyy="0.0017900" iyz="0" izz="0.0017900" /> -->
      <inertia ixx="0.00327313329" ixy="-0.00000460054" ixz="-0.00025121368" iyy="0.00316047802" iyz="0.00000313158" izz="0.00157642528"/>
    </inertial>
    <visual>
      <origin rpy="0 0 0" xyz="0 0 0"/>
      <geometry>
        <mesh filename="package://reemc_description/meshes/arm/arm_1.dae" scale="1 1 -1.0"/>
      </geometry>
      <material name="DarkGrey"/>
    </visual>
    <collision>
      <origin rpy="0 0 0" xyz="0 0 0"/>
      <geometry>
        <mesh filename="package://reemc_description/meshes/arm/arm_1_collision.stl" scale="1 1 -1.0"/>
      </geometry>
    </collision>
  </link>
  <joint name="arm_right_1_joint" type="revolute">
    <parent link="torso_2_link"/>
    <child link="arm_right_1_link"/>
    <origin rpy="-2.87979326579 0 0" xyz="0 -0.31827 0"/>
    <axis xyz="0 0 1"/>
    <limit effort="44.64" lower="-0.785398163397" upper="3.14159265359" velocity="2.7"/>
    <dynamics damping="1.0" friction="1.0"/>
    <safety_controller k_position="20" k_velocity="20" soft_lower_limit="-0.765398163397" soft_upper_limit="3.12159265359"/>
  </joint>
  <link name="arm_right_2_link">
    <inertial>
      <origin rpy="0 0 0" xyz="0.01435 -0.06294 0.01039"/>
      <mass value="1.60393"/>
      <!--<inertia ixx="0"  ixy="0"  ixz="0" iyy="0" iyz="0" izz="0" />-->
      <!-- NOTE: Assuming cylinder centered at CoM with r=0.05, h=0.05 with axis parallel to y coordinate -->
      <!-- <inertia ixx="0.0013417"  ixy="0"  ixz="0" iyy="0.0020125" iyz="0" izz="0.0013417" /> -->
      <inertia ixx="0.0046195621" ixy="-0.00056769245" ixz="0.00018376961" iyy="0.00185384237" iyz="-0.00078286958" izz="0.0049356022"/>
    </inertial>
    <visual>
      <origin rpy="0 0 0" xyz="0 0 0"/>
      <geometry>
        <mesh filename="package://reemc_description/meshes/arm/arm_2.dae" scale="1 1 -1.0"/>
      </geometry>
      <material name="DarkGrey"/>
    </visual>
    <collision>
      <origin rpy="0 0 0" xyz="0 0 0"/>
      <geometry>
        <mesh filename="package://reemc_description/meshes/arm/arm_2_collision.stl" scale="1 1 -1.0"/>
      </geometry>
    </collision>
  </link>
  <joint name="arm_right_2_joint" type="revolute">
    <parent link="arm_right_1_link"/>
    <child link="arm_right_2_link"/>
    <origin rpy="-1.57079632679 -1.308996939 1.57079632679" xyz="0 0 0.21749"/>
    <axis xyz="0 0 1"/>
    <limit effort="22.32" lower="-0.261799387799" upper="2.09439510239" velocity="3.66"/>
    <dynamics damping="1.0" friction="1.0"/>
    <safety_controller k_position="20" k_velocity="20" soft_lower_limit="-0.241799387799" soft_upper_limit="2.07439510239"/>
  </joint>
  <link name="arm_right_3_link">
    <inertial>
      <origin rpy="0 0 0" xyz="0.00606 -0.0113 0.05748"/>
      <mass value="1.64293"/>
      <!--<inertia ixx="0"  ixy="0"  ixz="0" iyy="0" iyz="0" izz="0" />-->
      <!-- NOTE: Assuming cylinder centered at CoM with r=0.05, h=0.05 with axis parallel to x coordinate -->
      <inertia ixx="0.00372686652" ixy="-0.00008722874" ixz="-0.00028800176" iyy="0.00344463026" iyz="0.00042776588" izz="0.00192229026"/>
    </inertial>
    <visual>
      <origin rpy="0 0 0" xyz="0 0 0"/>
      <geometry>
        <mesh filename="package://reemc_description/meshes/arm/arm_3.dae" scale="1 1 -1.0"/>
      </geometry>
      <material name="DarkGrey"/>
    </visual>
    <collision>
      <origin rpy="0 0 0" xyz="0 0 0"/>
      <geometry>
        <mesh filename="package://reemc_description/meshes/arm/arm_3_collision.stl" scale="1 1 -1.0"/>
      </geometry>
    </collision>
  </link>
  <joint name="arm_right_3_joint" type="revolute">
    <parent link="arm_right_2_link"/>
    <child link="arm_right_3_link"/>
    <origin rpy="1.57079632679 0 0" xyz="0.02 -0.142 0"/>
    <axis xyz="0 0 1"/>
    <limit effort="17.86" lower="-2.35619449019" upper="2.74889357189" velocity="4.58"/>
    <dynamics damping="1.0" friction="1.0"/>
    <safety_controller k_position="20" k_velocity="20" soft_lower_limit="-2.33619449019" soft_upper_limit="2.72889357189"/>
  </joint>
  <!--************************-->
  <!--        ELBOW           -->
  <!--************************-->
  <link name="arm_right_4_link">
    <inertial>
      <origin rpy="0 0 0" xyz="-0.04129 0.0118 -0.01387"/>
      <mass value="1.20222"/>
      <!--<inertia ixx="0"  ixy="0"  ixz="0" iyy="0" iyz="0" izz="0" />-->
      <!-- NOTE: Assuming cylinder centered at CoM with r=0.05, h=0.05 with axis parallel to x coordinate -->
      <!-- <inertia ixx="0.0012663"  ixy="0"  ixz="0" iyy="0.00084417" iyz="0" izz="0.00084417" /> -->
      <inertia ixx="0.00156355749" ixy="-0.000353141" ixz="0.00053402452" iyy="0.00277186194" iyz="-0.00015541973" izz="0.00307369106"/>
    </inertial>
    <visual>
      <origin rpy="0 0 0" xyz="0 0 0"/>
      <geometry>
        <mesh filename="package://reemc_description/meshes/arm/arm_4.dae" scale="1 1 -1.0"/>
      </geometry>
      <material name="DarkGrey"/>
    </visual>
    <collision>
      <origin rpy="0 0 0" xyz="0 0 0"/>
      <geometry>
        <mesh filename="package://reemc_description/meshes/arm/arm_4_collision.stl" scale="1 1 -1.0"/>
      </geometry>
    </collision>
  </link>
  <joint name="arm_right_4_joint" type="revolute">
    <parent link="arm_right_3_link"/>
    <child link="arm_right_4_link"/>
    <origin rpy="0 1.57079632679 0" xyz="0 -0.02 0.088"/>
    <axis xyz="0 0 1"/>
    <limit effort="17.86" lower="0" upper="2.26892802759" velocity="4.58"/>
    <dynamics damping="1.0" friction="1.0"/>
    <safety_controller k_position="20" k_velocity="20" soft_lower_limit="0.0" soft_upper_limit="2.24892802759"/>
  </joint>
  <gazebo reference="arm_right_1_link">
    <mu1>0.9</mu1>
    <mu2>0.9</mu2>
  </gazebo>
  <gazebo reference="arm_right_2_link">
    <mu1>0.9</mu1>
    <mu2>0.9</mu2>
  </gazebo>
  <gazebo reference="arm_right_3_link">
    <mu1>0.9</mu1>
    <mu2>0.9</mu2>
  </gazebo>
  <gazebo reference="arm_right_4_link">
    <mu1>0.9</mu1>
    <mu2>0.9</mu2>
  </gazebo>
  <gazebo reference="arm_right_1_joint">
    <implicitSpringDamper>1</implicitSpringDamper>
  </gazebo>
  <gazebo reference="arm_right_2_joint">
    <implicitSpringDamper>1</implicitSpringDamper>
  </gazebo>
  <gazebo reference="arm_right_3_joint">
    <implicitSpringDamper>1</implicitSpringDamper>
  </gazebo>
  <gazebo reference="arm_right_4_joint">
    <implicitSpringDamper>1</implicitSpringDamper>
  </gazebo>
  <!--************************-->
  <!--        WRIST           -->
  <!--************************-->
  <!--************************-->
  <!--        WRIST           -->
  <!--************************-->
  <link name="arm_right_5_link">
    <inertial>
      <origin rpy="0 0 0" xyz="-0.00044 0.00012 0.07445"/>
      <mass value="1.21524"/>
      <!-- <inertia ixx="0"  ixy="0"  ixz="0" iyy="0" iyz="0" izz="0" /> -->
      <!-- NOTE: Assuming cylinder centered at CoM with r=0.05, h=0.1 with axis parallel to z coordinate -->
      <!--         <inertia ixx="0.0027096"  ixy="0"  ixz="0" iyy="0.0027096" iyz="0" izz="0.0023225" /> -->
      <inertia ixx="0.00193499547" ixy="-0.00000027528" ixz="-0.00001268153" iyy="0.00177767506" iyz="-0.00000466638" izz="0.00057101196"/>
    </inertial>
    <visual>
      <origin rpy="0 0 0" xyz="0 0 0"/>
      <geometry>
        <mesh filename="package://reemc_description/meshes/arm/arm_5.dae" scale="1 1 -1.0"/>
      </geometry>
      <material name="LightGrey"/>
    </visual>
    <collision>
      <origin rpy="0 0 0" xyz="0 0 0"/>
      <geometry>
        <mesh filename="package://reemc_description/meshes/arm/arm_5_collision.stl" scale="1 1 -1.0"/>
      </geometry>
    </collision>
  </link>
  <joint name="arm_right_5_joint" type="revolute">
    <parent link="arm_right_4_link"/>
    <child link="arm_right_5_link"/>
    <origin rpy="0 -1.57079632679 0" xyz="-0.088 0.02 0"/>
    <axis xyz="0 0 1"/>
    <limit effort="3" lower="-2.09439510239" upper="2.09439510239" velocity="1.95"/>
    <!--TODO: Check effort value!-->
    <dynamics damping="1.0" friction="1.0"/>
    <safety_controller k_position="20" k_velocity="20" soft_lower_limit="-2.07439510239" soft_upper_limit="2.07439510239"/>
  </joint>
  <link name="arm_right_6_link">
    <inertial>
      <origin rpy="0 0 0" xyz="-0.00005 -0.00252 7e-05"/>
      <mass value="0.41597"/>
      <!-- <inertia ixx="0"  ixy="0"  ixz="0" iyy="0" iyz="0" izz="0" /> -->
      <!-- NOTE: Assuming cylinder centered at CoM with r=0.02, h=0.08 with axis parallel to z coordinate -->
      <!--         <inertia ixx="0.0001615"  ixy="0"  ixz="0" iyy="0.0001615" iyz="0" izz="0.000051" /> -->
      <inertia ixx="0.00020339659" ixy="-0.00000071703" ixz="-0.00000006654" iyy="0.00015240261" iyz="0.00000014315" izz="0.0001671881"/>
    </inertial>
    <visual>
      <origin rpy="0 0 0" xyz="0 0 0"/>
      <geometry>
        <mesh filename="package://reemc_description/meshes/arm/arm_6.dae" scale="1 1 -1.0"/>
      </geometry>
      <material name="LightGrey"/>
    </visual>
    <collision>
      <origin rpy="0 0 0" xyz="0 0 0"/>
      <geometry>
        <cylinder length="0.0385" radius="0.04"/>
      </geometry>
    </collision>
  </link>
  <joint name="arm_right_6_joint" type="revolute">
    <parent link="arm_right_5_link"/>
    <child link="arm_right_6_link"/>
    <origin rpy="-1.57079632679 0 0" xyz="0 0 0.15"/>
    <axis xyz="0 0 1"/>
    <limit effort="6.6" lower="-1.57079632679" upper="1.57079632679" velocity="1.76"/>
    <dynamics damping="1.0" friction="1.0"/>
    <safety_controller k_position="20" k_velocity="20" soft_lower_limit="-1.55079632679" soft_upper_limit="1.55079632679"/>
  </joint>
  <link name="arm_right_7_link">
    <inertial>
      <!--TODO: Verify these inertial parameters-->
      <origin rpy="0 0 0" xyz="-0.00004 0 -0.02887"/>
      <mass value="0.06697"/>
      <!-- <inertia ixx="0"  ixy="0"  ixz="0" iyy="0" iyz="0" izz="0" /> -->
      <!-- NOTE: Assuming point mass -->
      <!--         <inertia ixx="0"  ixy="0"  ixz="0" iyy="0" iyz="0" izz="0" /> -->
      <inertia ixx="0.0000123718" ixy="0.00000000002" ixz="0.00000002403" iyy="0.00001242132" iyz="0.00000000001" izz="0.0000059514"/>
    </inertial>
    <visual>
      <origin rpy="0 0 0" xyz="0 0 0.046"/>
      <geometry>
        <cylinder length="0.005" radius="0.02"/>
      </geometry>
      <material name="DarkGrey"/>
    </visual>
    <collision>
      <origin rpy="0 0 0" xyz="0 0 0.0345"/>
      <geometry>
        <cylinder length="0.023" radius="0.02"/>
      </geometry>
    </collision>
  </link>
  <joint name="arm_right_7_joint" type="revolute">
    <parent link="arm_right_6_link"/>
    <child link="arm_right_7_link"/>
    <origin rpy="1.57079632679 0 0" xyz="0 0 0"/>
    <axis xyz="0 0 1"/>
    <limit effort="6.6" lower="-2.09439510239" upper="2.09439510239" velocity="1.76"/>
    <dynamics damping="1.0" friction="1.0"/>
    <safety_controller k_position="20" k_velocity="20" soft_lower_limit="-2.07439510239" soft_upper_limit="2.07439510239"/>
  </joint>
  <gazebo reference="arm_right_5_link">
    <mu1>0.9</mu1>
    <mu2>0.9</mu2>
  </gazebo>
  <gazebo reference="arm_right_6_link">
    <mu1>0.9</mu1>
    <mu2>0.9</mu2>
  </gazebo>
  <gazebo reference="arm_right_7_link">
    <mu1>0.9</mu1>
    <mu2>0.9</mu2>
  </gazebo>
  <gazebo reference="arm_right_5_joint">
    <implicitSpringDamper>1</implicitSpringDamper>
  </gazebo>
  <gazebo reference="arm_right_6_joint">
    <implicitSpringDamper>1</implicitSpringDamper>
  </gazebo>
  <gazebo reference="arm_right_7_joint">
    <implicitSpringDamper>1</implicitSpringDamper>
  </gazebo>
  <!-- extensions -->
  <transmission name="arm_right_5_trans">
    <type>transmission_interface/SimpleTransmission</type>
    <actuator name="arm_right_5_motor">
      <mechanicalReduction>1.0</mechanicalReduction>
    </actuator>
    <joint name="arm_right_5_joint">
      <hardwareInterface>hardware_interface/PositionJointInterface</hardwareInterface>
    </joint>
  </transmission>
  <transmission name="wrist_right_trans">
    <type>transmission_interface/DifferentialTransmission</type>
    <actuator name="arm_right_6_motor">
      <role>actuator1</role>
      <mechanicalReduction>-1.0</mechanicalReduction>
    </actuator>
    <actuator name="arm_right_7_motor">
      <role>actuator2</role>
      <mechanicalReduction>1.0</mechanicalReduction>
    </actuator>
    <joint name="arm_right_6_joint">
      <role>joint1</role>
      <offset>0.0</offset>
      <mechanicalReduction>-1.0</mechanicalReduction>
      <hardwareInterface>hardware_interface/PositionJointInterface</hardwareInterface>
    </joint>
    <joint name="arm_right_7_joint">
      <role>joint2</role>
      <offset>0.0</offset>
      <mechanicalReduction>-1.0</mechanicalReduction>
      <hardwareInterface>hardware_interface/PositionJointInterface</hardwareInterface>
    </joint>
  </transmission>
  <!--***********************-->
  <!--        TOOL           -->
  <!--***********************-->
  <link name="arm_right_tool_link">
    <inertial>
      <mass value="0.1"/>
      <inertia ixx="0.0" ixy="0.0" ixz="0.0" iyy="0.0" iyz="0.0" izz="0.0"/>
    </inertial>
    <visual>
      <origin rpy="0 1.57079632679 0" xyz="0.001 0 0"/>
      <geometry>
        <cylinder length="0.005" radius="0.005"/>
      </geometry>
      <material name="LightGrey"/>
    </visual>
    <collision>
      <origin rpy="0 1.57079632679 0" xyz="0.001 0 0"/>
      <geometry>
        <cylinder length="0.005" radius="0.005"/>
      </geometry>
    </collision>
  </link>
  <joint name="arm_right_tool_joint" type="fixed">
    <parent link="arm_right_7_link"/>
    <child link="arm_right_tool_link"/>
    <origin rpy="1.57079632679 -1.57079632679 0" xyz="0 0 0.046"/>
  </joint>
  <!-- extensions -->
  <transmission name="arm_right_1_trans">
    <type>transmission_interface/SimpleTransmission</type>
    <actuator name="arm_right_1_motor">
      <mechanicalReduction>1.0</mechanicalReduction>
    </actuator>
    <joint name="arm_right_1_joint">
      <hardwareInterface>hardware_interface/PositionJointInterface</hardwareInterface>
    </joint>
  </transmission>
  <transmission name="arm_right_2_trans">
    <type>transmission_interface/SimpleTransmission</type>
    <actuator name="arm_right_2_motor">
      <mechanicalReduction>1.0</mechanicalReduction>
    </actuator>
    <joint name="arm_right_2_joint">
      <hardwareInterface>hardware_interface/PositionJointInterface</hardwareInterface>
    </joint>
  </transmission>
  <transmission name="arm_right_3_trans">
    <type>transmission_interface/SimpleTransmission</type>
    <actuator name="arm_right_3_motor">
      <mechanicalReduction>1.0</mechanicalReduction>
    </actuator>
    <joint name="arm_right_3_joint">
      <hardwareInterface>hardware_interface/PositionJointInterface</hardwareInterface>
    </joint>
  </transmission>
  <transmission name="arm_right_4_trans">
    <type>transmission_interface/SimpleTransmission</type>
    <actuator name="arm_right_4_motor">
      <mechanicalReduction>1.0</mechanicalReduction>
    </actuator>
    <joint name="arm_right_4_joint">
      <hardwareInterface>hardware_interface/PositionJointInterface</hardwareInterface>
    </joint>
  </transmission>
  <!--************************-->
  <!--        SHOULDER        -->
  <!--************************-->
  <link name="arm_left_1_link">
    <inertial>
      <origin rpy="0 0 0" xyz="0.00701 -0.00011 -0.18627"/>
      <mass value="1.53614"/>
      <!--        <inertia ixx="0"  ixy="0"  ixz="0" iyy="0" iyz="0" izz="0" /> -->
      <!--         NOTE: Assuming cylinder centered at CoM with r=0.05, h=0.05 with axis parallel to x coordinate -->
      <!--        <inertia ixx="0.0026850"  ixy="0"  ixz="0" iyy="0.0017900" iyz="0" izz="0.0017900" /> -->
      <inertia ixx="0.00327313329" ixy="-0.00000460054" ixz="-0.00025121368" iyy="0.00316047802" iyz="0.00000313158" izz="0.00157642528"/>
    </inertial>
    <visual>
      <origin rpy="0 0 0" xyz="0 0 0"/>
      <geometry>
        <mesh filename="package://reemc_description/meshes/arm/arm_1.dae" scale="1 1 1.0"/>
      </geometry>
      <material name="DarkGrey"/>
    </visual>
    <collision>
      <origin rpy="0 0 0" xyz="0 0 0"/>
      <geometry>
        <mesh filename="package://reemc_description/meshes/arm/arm_1_collision.stl" scale="1 1 1.0"/>
      </geometry>
    </collision>
  </link>
  <joint name="arm_left_1_joint" type="revolute">
    <parent link="torso_2_link"/>
    <child link="arm_left_1_link"/>
    <origin rpy="2.87979326579 0 0" xyz="0 -0.31827 0"/>
    <axis xyz="0 0 1"/>
    <limit effort="44.64" lower="-0.785398163397" upper="3.14159265359" velocity="2.7"/>
    <dynamics damping="1.0" friction="1.0"/>
    <safety_controller k_position="20" k_velocity="20" soft_lower_limit="-0.765398163397" soft_upper_limit="3.12159265359"/>
  </joint>
  <link name="arm_left_2_link">
    <inertial>
      <origin rpy="0 0 0" xyz="0.01435 -0.06294 -0.01039"/>
      <mass value="1.60393"/>
      <!--<inertia ixx="0"  ixy="0"  ixz="0" iyy="0" iyz="0" izz="0" />-->
      <!-- NOTE: Assuming cylinder centered at CoM with r=0.05, h=0.05 with axis parallel to y coordinate -->
      <!-- <inertia ixx="0.0013417"  ixy="0"  ixz="0" iyy="0.0020125" iyz="0" izz="0.0013417" /> -->
      <inertia ixx="0.0046195621" ixy="-0.00056769245" ixz="0.00018376961" iyy="0.00185384237" iyz="-0.00078286958" izz="0.0049356022"/>
    </inertial>
    <visual>
      <origin rpy="0 0 0" xyz="0 0 0"/>
      <geometry>
        <mesh filename="package://reemc_description/meshes/arm/arm_2.dae" scale="1 1 1.0"/>
      </geometry>
      <material name="DarkGrey"/>
    </visual>
    <collision>
      <origin rpy="0 0 0" xyz="0 0 0"/>
      <geometry>
        <mesh filename="package://reemc_description/meshes/arm/arm_2_collision.stl" scale="1 1 1.0"/>
      </geometry>
    </collision>
  </link>
  <joint name="arm_left_2_joint" type="revolute">
    <parent link="arm_left_1_link"/>
    <child link="arm_left_2_link"/>
    <origin rpy="1.57079632679 1.308996939 1.57079632679" xyz="0 0 -0.21749"/>
    <axis xyz="0 0 1"/>
    <limit effort="22.32" lower="-0.261799387799" upper="2.09439510239" velocity="3.66"/>
    <dynamics damping="1.0" friction="1.0"/>
    <safety_controller k_position="20" k_velocity="20" soft_lower_limit="-0.241799387799" soft_upper_limit="2.07439510239"/>
  </joint>
  <link name="arm_left_3_link">
    <inertial>
      <origin rpy="0 0 0" xyz="0.00606 -0.0113 -0.05748"/>
      <mass value="1.64293"/>
      <!--<inertia ixx="0"  ixy="0"  ixz="0" iyy="0" iyz="0" izz="0" />-->
      <!-- NOTE: Assuming cylinder centered at CoM with r=0.05, h=0.05 with axis parallel to x coordinate -->
      <inertia ixx="0.00372686652" ixy="-0.00008722874" ixz="-0.00028800176" iyy="0.00344463026" iyz="0.00042776588" izz="0.00192229026"/>
    </inertial>
    <visual>
      <origin rpy="0 0 0" xyz="0 0 0"/>
      <geometry>
        <mesh filename="package://reemc_description/meshes/arm/arm_3.dae" scale="1 1 1.0"/>
      </geometry>
      <material name="DarkGrey"/>
    </visual>
    <collision>
      <origin rpy="0 0 0" xyz="0 0 0"/>
      <geometry>
        <mesh filename="package://reemc_description/meshes/arm/arm_3_collision.stl" scale="1 1 1.0"/>
      </geometry>
    </collision>
  </link>
  <joint name="arm_left_3_joint" type="revolute">
    <parent link="arm_left_2_link"/>
    <child link="arm_left_3_link"/>
    <origin rpy="-1.57079632679 0 0" xyz="0.02 -0.142 0"/>
    <axis xyz="0 0 1"/>
    <limit effort="17.86" lower="-2.35619449019" upper="2.74889357189" velocity="4.58"/>
    <dynamics damping="1.0" friction="1.0"/>
    <safety_controller k_position="20" k_velocity="20" soft_lower_limit="-2.33619449019" soft_upper_limit="2.72889357189"/>
  </joint>
  <!--************************-->
  <!--        ELBOW           -->
  <!--************************-->
  <link name="arm_left_4_link">
    <inertial>
      <origin rpy="0 0 0" xyz="-0.04129 0.0118 0.01387"/>
      <mass value="1.20222"/>
      <!--<inertia ixx="0"  ixy="0"  ixz="0" iyy="0" iyz="0" izz="0" />-->
      <!-- NOTE: Assuming cylinder centered at CoM with r=0.05, h=0.05 with axis parallel to x coordinate -->
      <!-- <inertia ixx="0.0012663"  ixy="0"  ixz="0" iyy="0.00084417" iyz="0" izz="0.00084417" /> -->
      <inertia ixx="0.00156355749" ixy="-0.000353141" ixz="0.00053402452" iyy="0.00277186194" iyz="-0.00015541973" izz="0.00307369106"/>
    </inertial>
    <visual>
      <origin rpy="0 0 0" xyz="0 0 0"/>
      <geometry>
        <mesh filename="package://reemc_description/meshes/arm/arm_4.dae" scale="1 1 1.0"/>
      </geometry>
      <material name="DarkGrey"/>
    </visual>
    <collision>
      <origin rpy="0 0 0" xyz="0 0 0"/>
      <geometry>
        <mesh filename="package://reemc_description/meshes/arm/arm_4_collision.stl" scale="1 1 1.0"/>
      </geometry>
    </collision>
  </link>
  <joint name="arm_left_4_joint" type="revolute">
    <parent link="arm_left_3_link"/>
    <child link="arm_left_4_link"/>
    <origin rpy="0 -1.57079632679 0" xyz="0 -0.02 -0.088"/>
    <axis xyz="0 0 1"/>
    <limit effort="17.86" lower="0" upper="2.26892802759" velocity="4.58"/>
    <dynamics damping="1.0" friction="1.0"/>
    <safety_controller k_position="20" k_velocity="20" soft_lower_limit="0.0" soft_upper_limit="2.24892802759"/>
  </joint>
  <gazebo reference="arm_left_1_link">
    <mu1>0.9</mu1>
    <mu2>0.9</mu2>
  </gazebo>
  <gazebo reference="arm_left_2_link">
    <mu1>0.9</mu1>
    <mu2>0.9</mu2>
  </gazebo>
  <gazebo reference="arm_left_3_link">
    <mu1>0.9</mu1>
    <mu2>0.9</mu2>
  </gazebo>
  <gazebo reference="arm_left_4_link">
    <mu1>0.9</mu1>
    <mu2>0.9</mu2>
  </gazebo>
  <gazebo reference="arm_left_1_joint">
    <implicitSpringDamper>1</implicitSpringDamper>
  </gazebo>
  <gazebo reference="arm_left_2_joint">
    <implicitSpringDamper>1</implicitSpringDamper>
  </gazebo>
  <gazebo reference="arm_left_3_joint">
    <implicitSpringDamper>1</implicitSpringDamper>
  </gazebo>
  <gazebo reference="arm_left_4_joint">
    <implicitSpringDamper>1</implicitSpringDamper>
  </gazebo>
  <!--************************-->
  <!--        WRIST           -->
  <!--************************-->
  <!--************************-->
  <!--        WRIST           -->
  <!--************************-->
  <link name="arm_left_5_link">
    <inertial>
      <origin rpy="0 0 0" xyz="-0.00044 0.00012 -0.07445"/>
      <mass value="1.21524"/>
      <!-- <inertia ixx="0"  ixy="0"  ixz="0" iyy="0" iyz="0" izz="0" /> -->
      <!-- NOTE: Assuming cylinder centered at CoM with r=0.05, h=0.1 with axis parallel to z coordinate -->
      <!--         <inertia ixx="0.0027096"  ixy="0"  ixz="0" iyy="0.0027096" iyz="0" izz="0.0023225" /> -->
      <inertia ixx="0.00193499547" ixy="-0.00000027528" ixz="-0.00001268153" iyy="0.00177767506" iyz="-0.00000466638" izz="0.00057101196"/>
    </inertial>
    <visual>
      <origin rpy="0 0 0" xyz="0 0 0"/>
      <geometry>
        <mesh filename="package://reemc_description/meshes/arm/arm_5.dae" scale="1 1 1.0"/>
      </geometry>
      <material name="LightGrey"/>
    </visual>
    <collision>
      <origin rpy="0 0 0" xyz="0 0 0"/>
      <geometry>
        <mesh filename="package://reemc_description/meshes/arm/arm_5_collision.stl" scale="1 1 1.0"/>
      </geometry>
    </collision>
  </link>
  <joint name="arm_left_5_joint" type="revolute">
    <parent link="arm_left_4_link"/>
    <child link="arm_left_5_link"/>
    <origin rpy="0 1.57079632679 0" xyz="-0.088 0.02 0"/>
    <axis xyz="0 0 1"/>
    <limit effort="3" lower="-2.09439510239" upper="2.09439510239" velocity="1.95"/>
    <!--TODO: Check effort value!-->
    <dynamics damping="1.0" friction="1.0"/>
    <safety_controller k_position="20" k_velocity="20" soft_lower_limit="-2.07439510239" soft_upper_limit="2.07439510239"/>
  </joint>
  <link name="arm_left_6_link">
    <inertial>
      <origin rpy="0 0 0" xyz="-0.00005 -0.00252 -7e-05"/>
      <mass value="0.41597"/>
      <!-- <inertia ixx="0"  ixy="0"  ixz="0" iyy="0" iyz="0" izz="0" /> -->
      <!-- NOTE: Assuming cylinder centered at CoM with r=0.02, h=0.08 with axis parallel to z coordinate -->
      <!--         <inertia ixx="0.0001615"  ixy="0"  ixz="0" iyy="0.0001615" iyz="0" izz="0.000051" /> -->
      <inertia ixx="0.00020339659" ixy="-0.00000071703" ixz="-0.00000006654" iyy="0.00015240261" iyz="0.00000014315" izz="0.0001671881"/>
    </inertial>
    <visual>
      <origin rpy="0 0 0" xyz="0 0 0"/>
      <geometry>
        <mesh filename="package://reemc_description/meshes/arm/arm_6.dae" scale="1 1 1.0"/>
      </geometry>
      <material name="LightGrey"/>
    </visual>
    <collision>
      <origin rpy="0 0 0" xyz="0 0 0"/>
      <geometry>
        <cylinder length="0.0385" radius="0.04"/>
      </geometry>
    </collision>
  </link>
  <joint name="arm_left_6_joint" type="revolute">
    <parent link="arm_left_5_link"/>
    <child link="arm_left_6_link"/>
    <origin rpy="1.57079632679 0 0" xyz="0 0 -0.15"/>
    <axis xyz="0 0 1"/>
    <limit effort="6.6" lower="-1.57079632679" upper="1.57079632679" velocity="1.76"/>
    <dynamics damping="1.0" friction="1.0"/>
    <safety_controller k_position="20" k_velocity="20" soft_lower_limit="-1.55079632679" soft_upper_limit="1.55079632679"/>
  </joint>
  <link name="arm_left_7_link">
    <inertial>
      <!--TODO: Verify these inertial parameters-->
      <origin rpy="0 0 0" xyz="-0.00004 0 0.02887"/>
      <mass value="0.06697"/>
      <!-- <inertia ixx="0"  ixy="0"  ixz="0" iyy="0" iyz="0" izz="0" /> -->
      <!-- NOTE: Assuming point mass -->
      <!--         <inertia ixx="0"  ixy="0"  ixz="0" iyy="0" iyz="0" izz="0" /> -->
      <inertia ixx="0.0000123718" ixy="0.00000000002" ixz="0.00000002403" iyy="0.00001242132" iyz="0.00000000001" izz="0.0000059514"/>
    </inertial>
    <visual>
      <origin rpy="0 0 0" xyz="0 0 -0.046"/>
      <geometry>
        <cylinder length="0.005" radius="0.02"/>
      </geometry>
      <material name="DarkGrey"/>
    </visual>
    <collision>
      <origin rpy="0 0 0" xyz="0 0 -0.0345"/>
      <geometry>
        <cylinder length="0.023" radius="0.02"/>
      </geometry>
    </collision>
  </link>
  <joint name="arm_left_7_joint" type="revolute">
    <parent link="arm_left_6_link"/>
    <child link="arm_left_7_link"/>
    <origin rpy="-1.57079632679 0 0" xyz="0 0 0"/>
    <axis xyz="0 0 1"/>
    <limit effort="6.6" lower="-2.09439510239" upper="2.09439510239" velocity="1.76"/>
    <dynamics damping="1.0" friction="1.0"/>
    <safety_controller k_position="20" k_velocity="20" soft_lower_limit="-2.07439510239" soft_upper_limit="2.07439510239"/>
  </joint>
  <gazebo reference="arm_left_5_link">
    <mu1>0.9</mu1>
    <mu2>0.9</mu2>
  </gazebo>
  <gazebo reference="arm_left_6_link">
    <mu1>0.9</mu1>
    <mu2>0.9</mu2>
  </gazebo>
  <gazebo reference="arm_left_7_link">
    <mu1>0.9</mu1>
    <mu2>0.9</mu2>
  </gazebo>
  <gazebo reference="arm_left_5_joint">
    <implicitSpringDamper>1</implicitSpringDamper>
  </gazebo>
  <gazebo reference="arm_left_6_joint">
    <implicitSpringDamper>1</implicitSpringDamper>
  </gazebo>
  <gazebo reference="arm_left_7_joint">
    <implicitSpringDamper>1</implicitSpringDamper>
  </gazebo>
  <!-- extensions -->
  <transmission name="arm_left_5_trans">
    <type>transmission_interface/SimpleTransmission</type>
    <actuator name="arm_left_5_motor">
      <mechanicalReduction>1.0</mechanicalReduction>
    </actuator>
    <joint name="arm_left_5_joint">
      <hardwareInterface>hardware_interface/PositionJointInterface</hardwareInterface>
    </joint>
  </transmission>
  <transmission name="wrist_left_trans">
    <type>transmission_interface/DifferentialTransmission</type>
    <actuator name="arm_left_6_motor">
      <role>actuator1</role>
      <mechanicalReduction>-1.0</mechanicalReduction>
    </actuator>
    <actuator name="arm_left_7_motor">
      <role>actuator2</role>
      <mechanicalReduction>1.0</mechanicalReduction>
    </actuator>
    <joint name="arm_left_6_joint">
      <role>joint1</role>
      <offset>0.0</offset>
      <mechanicalReduction>-1.0</mechanicalReduction>
      <hardwareInterface>hardware_interface/PositionJointInterface</hardwareInterface>
    </joint>
    <joint name="arm_left_7_joint">
      <role>joint2</role>
      <offset>0.0</offset>
      <mechanicalReduction>1.0</mechanicalReduction>
      <hardwareInterface>hardware_interface/PositionJointInterface</hardwareInterface>
    </joint>
  </transmission>
  <!--***********************-->
  <!--        TOOL           -->
  <!--***********************-->
  <link name="arm_left_tool_link">
    <inertial>
      <mass value="0.1"/>
      <inertia ixx="0.0" ixy="0.0" ixz="0.0" iyy="0.0" iyz="0.0" izz="0.0"/>
    </inertial>
    <visual>
      <origin rpy="0 1.57079632679 0" xyz="0.001 0 0"/>
      <geometry>
        <cylinder length="0.005" radius="0.005"/>
      </geometry>
      <material name="LightGrey"/>
    </visual>
    <collision>
      <origin rpy="0 1.57079632679 0" xyz="0.001 0 0"/>
      <geometry>
        <cylinder length="0.005" radius="0.005"/>
      </geometry>
    </collision>
  </link>
  <joint name="arm_left_tool_joint" type="fixed">
    <parent link="arm_left_7_link"/>
    <child link="arm_left_tool_link"/>
    <origin rpy="1.57079632679 1.57079632679 0" xyz="0 0 -0.046"/>
  </joint>
  <!-- extensions -->
  <transmission name="arm_left_1_trans">
    <type>transmission_interface/SimpleTransmission</type>
    <actuator name="arm_left_1_motor">
      <mechanicalReduction>1.0</mechanicalReduction>
    </actuator>
    <joint name="arm_left_1_joint">
      <hardwareInterface>hardware_interface/PositionJointInterface</hardwareInterface>
    </joint>
  </transmission>
  <transmission name="arm_left_2_trans">
    <type>transmission_interface/SimpleTransmission</type>
    <actuator name="arm_left_2_motor">
      <mechanicalReduction>1.0</mechanicalReduction>
    </actuator>
    <joint name="arm_left_2_joint">
      <hardwareInterface>hardware_interface/PositionJointInterface</hardwareInterface>
    </joint>
  </transmission>
  <transmission name="arm_left_3_trans">
    <type>transmission_interface/SimpleTransmission</type>
    <actuator name="arm_left_3_motor">
      <mechanicalReduction>1.0</mechanicalReduction>
    </actuator>
    <joint name="arm_left_3_joint">
      <hardwareInterface>hardware_interface/PositionJointInterface</hardwareInterface>
    </joint>
  </transmission>
  <transmission name="arm_left_4_trans">
    <type>transmission_interface/SimpleTransmission</type>
    <actuator name="arm_left_4_motor">
      <mechanicalReduction>1.0</mechanicalReduction>
    </actuator>
    <joint name="arm_left_4_joint">
      <hardwareInterface>hardware_interface/PositionJointInterface</hardwareInterface>
    </joint>
  </transmission>
  <!-- Palm -->
  <joint name="hand_right_palm_joint" type="fixed">
    <parent link="arm_right_tool_link"/>
    <child link="hand_right_palm_link"/>
    <origin rpy="0 0 0" xyz="0 0 0"/>
  </joint>
  <link name="hand_right_palm_link">
    <inertial>
      <origin rpy="0 0 0" xyz="0.05904 -0.00925 -0.00075 "/>
      <!--TODO: This does not make sense!, there must be a bug in how Gazebo bungles the CoM of a chain of fixed joints-->
      <mass value="0.68275"/>
      <inertia ixx="0.00045643484" ixy="0.00001885321" ixz="-0.0000103596" iyy="0.00076077407" iyz="-0.00000266311" izz="0.00052521525"/>
    </inertial>
    <visual>
      <origin rpy="0 0 0" xyz="0 0 0"/>
      <geometry>
        <mesh filename="package://reemc_description/meshes/hand/hand_palm.dae" scale="1 -1.0 1"/>
      </geometry>
      <material name="LightGrey"/>
    </visual>
    <collision>
      <origin rpy="0 0 0" xyz="0 0 0"/>
      <geometry>
        <mesh filename="package://reemc_description/meshes/hand/hand_palm_collision.stl" scale="1 -1.0 1"/>
      </geometry>
    </collision>
  </link>
  <gazebo reference="hand_right_palm_link">
    <kp>1000000.0</kp>
    <kd>100.0</kd>
    <mu1>1.0</mu1>
    <mu2>1.0</mu2>
    <fdir1>0 0 1</fdir1>
    <maxVel>1.0</maxVel>
    <minDepth>0.00</minDepth>
  </gazebo>
  <xacro:hand_gazebo name="hand_right_palm"/>
  <!-- Thumb -->
  <joint name="hand_right_thumb_joint" type="revolute">
    <parent link="hand_right_palm_link"/>
    <child link="hand_right_thumb_link"/>
    <origin rpy="3.14159265359 1.79768912955 0.226892802759" xyz="0.03649 0.008  0.02"/>
    <axis xyz="0 0 1"/>
    <limit effort="2.0" lower="0.0" upper="1.57079632679" velocity="2.0"/>
    <dynamics damping="0.5" friction="0.0"/>
    <safety_controller k_position="20" k_velocity="20" soft_lower_limit="0.0" soft_upper_limit="1.55079632679"/>
  </joint>
  <link name="hand_right_thumb_link">
    <inertial>
      <origin rpy="0 0 0" xyz="0.00049 0.00451 -0.04179"/>
      <mass value="0.07088"/>
      <inertia ixx="0.0000699364" ixy="0.00000345915" ixz="0.00000425008" iyy="0.00002675459" iyz="0.00002381865" izz="0.00004787167"/>
    </inertial>
    <visual>
      <origin rpy="0 0 0" xyz="0 0 0"/>
      <geometry>
        <mesh filename="package://reemc_description/meshes/hand/hand_thumb.dae" scale="1 1 -1.0"/>
      </geometry>
      <material name="LightGrey"/>
    </visual>
    <collision>
      <origin rpy="0 0 0" xyz="0 0 0"/>
      <geometry>
        <mesh filename="package://reemc_description/meshes/hand/hand_thumb_collision.stl" scale="1 1 -1.0"/>
      </geometry>
    </collision>
  </link>
  <gazebo reference="hand_right_thumb_link">
    <kp>1000000.0</kp>
    <kd>100.0</kd>
    <mu1>1.0</mu1>
    <mu2>1.0</mu2>
    <fdir1>0 0 1</fdir1>
    <maxVel>1.0</maxVel>
    <minDepth>0.00</minDepth>
  </gazebo>
  <gazebo reference="hand_right_thumb_joint">
    <implicitSpringDamper>1</implicitSpringDamper>
  </gazebo>
  <!-- Grasping frame -->
  <!-- grasp planner will approach along x-axis -->
  <joint name="hand_right_grasping_frame_joint" type="fixed">
    <parent link="hand_right_palm_link"/>
    <child link="hand_right_grasping_frame"/>
    <origin rpy="0 0 0" xyz="0.055 0.054 0.018"/>
  </joint>
  <link name="hand_right_grasping_frame">
    <inertial>
      <origin rpy="0 0 0" xyz="0 0 0"/>
      <mass value="0.01"/>
      <!-- matrix below must not be zero, or Gazebo won't load -->
      <inertia ixx="0.00001" ixy="0.0" ixz="0.0" iyy="0.00001" iyz="0.0" izz="0.00001"/>
    </inertial>
  </link>
  <transmission name="hand_right_thumb_trans">
    <type>transmission_interface/SimpleTransmission</type>
    <actuator name="hand_right_thumb_motor">
      <mechanicalReduction>1</mechanicalReduction>
    </actuator>
    <joint name="hand_right_thumb_joint">
      <hardwareInterface>hardware_interface/PositionJointInterface</hardwareInterface>
    </joint>
  </transmission>
  <!-- Index finger -->
  <!-- Actuated joint -->
  <joint name="hand_right_index_joint" type="revolute">
    <parent link="hand_right_palm_link"/>
    <child link="hand_right_index_link"/>
    <origin rpy="0.0 0 1.57079632679" xyz="0.101 0.0025 0.0165"/>
    <axis xyz="0 0 1"/>
    <limit effort="2.0" lower="0.0" upper="4.36332312999" velocity="2.0"/>
    <!-- TODO: Tune values -->
    <dynamics damping="0.5" friction="0.0"/>
    <safety_controller k_position="20" k_velocity="20" soft_lower_limit="0.0" soft_upper_limit="4.34332312999"/>
  </joint>
  <link name="hand_right_index_link">
    <inertial>
      <origin rpy="0 0 0" xyz="0.00175 -0.01837 -0.00198"/>
      <mass value="0.055"/>
      <inertia ixx="0.00001450121" ixy="-0.00000065488" ixz="-0.00000039654" iyy="0.0000072995" iyz="0.00000012168" izz="0.00001262409"/>
    </inertial>
    <visual>
      <origin rpy="0 0 0" xyz="0 0 0"/>
      <geometry>
        <sphere radius="0.001"/>
      </geometry>
      <material name="LightGrey"/>
    </visual>
    <collision>
      <origin rpy="0 0 0" xyz="0 0 0"/>
      <geometry>
        <sphere radius="0.001"/>
      </geometry>
    </collision>
  </link>
  <!-- Read-only phalanxes-->
  <joint name="hand_right_index_1_joint" type="revolute">
    <parent link="hand_right_palm_link"/>
    <child link="hand_right_index_1_link"/>
    <origin rpy="0.0 0 1.57079632679" xyz="0.101 0.0025 0.0165"/>
    <axis xyz="0 0 1"/>
    <limit effort="2.0" lower="0.0" upper="1.57079632679" velocity="2.0"/>
    <dynamics damping="0.5" friction="0.0"/>
    <mimic joint="hand_right_index_joint" multiplier="0.36" offset="0.0"/>
  </joint>
  <link name="hand_right_index_1_link">
    <inertial>
      <origin rpy="0 0 0" xyz="0.00175 -0.01837 -0.00198"/>
      <mass value="0.055"/>
      <inertia ixx="0.00001450121" ixy="-0.00000065488" ixz="-0.00000039654" iyy="0.0000072995" iyz="0.00000012168" izz="0.00001262409"/>
    </inertial>
    <visual>
      <origin rpy="0 0 0" xyz="0 0 0"/>
      <geometry>
        <mesh filename="package://reemc_description/meshes/hand/hand_finger_1.dae" scale="1 1 -1.0"/>
      </geometry>
      <material name="LightGrey"/>
    </visual>
    <collision>
      <origin rpy="0 0 0" xyz="0 0 0"/>
      <geometry>
        <mesh filename="package://reemc_description/meshes/hand/hand_finger_1_collision.stl" scale="1 1 -1.0"/>
      </geometry>
    </collision>
  </link>
  <joint name="hand_right_index_2_joint" type="revolute">
    <parent link="hand_right_index_1_link"/>
    <child link="hand_right_index_2_link"/>
    <origin rpy="0 0 0" xyz="0.00357 -0.04084 0"/>
    <axis xyz="0 0 1"/>
    <limit effort="1.0" lower="0.0" upper="1.3962634016" velocity="2.0"/>
    <dynamics damping="0.5" friction="0.0"/>
    <mimic joint="hand_right_index_joint" multiplier="0.32" offset="0.0"/>
  </joint>
  <link name="hand_right_index_2_link">
    <inertial>
      <origin rpy="0 0 0" xyz="0.00181 -0.01275 -0.00064"/>
      <mass value="0.02972"/>
      <inertia ixx="0.00000428193" ixy="-0.00000049978" ixz="-0.00000002985" iyy="0.00000254434" iyz="0.00000007762" izz="0.00000345152"/>
    </inertial>
    <visual>
      <origin rpy="0 0 0" xyz="0 0 0"/>
      <geometry>
        <mesh filename="package://reemc_description/meshes/hand/hand_finger_2.dae" scale="1 1 -1.0"/>
      </geometry>
      <material name="LightGrey"/>
    </visual>
    <collision>
      <origin rpy="0 0 0" xyz="0 0 0"/>
      <geometry>
        <mesh filename="package://reemc_description/meshes/hand/hand_finger_2_collision.stl" scale="1 1 -1.0"/>
      </geometry>
    </collision>
  </link>
  <joint name="hand_right_index_3_joint" type="revolute">
    <parent link="hand_right_index_2_link"/>
    <child link="hand_right_index_3_link"/>
    <origin rpy="0 0 0" xyz="0.00572 -0.0269 0"/>
    <axis xyz="0 0 1"/>
    <limit effort="1.0" lower="0.0" upper="1.3962634016" velocity="2.0"/>
    <dynamics damping="0.5" friction="0.0"/>
    <mimic joint="hand_right_index_joint" multiplier="0.32" offset="0.0"/>
  </joint>
  <link name="hand_right_index_3_link">
    <inertial>
      <origin rpy="0 0 0" xyz="0 -0.00704 0.00019"/>
      <mass value="0.01522"/>
      <inertia ixx="0.00000128478" ixy="-0.00000008056" ixz="-0.00000001698" iyy="0.00000080139" iyz="-0.00000002884" izz="0.00000090928"/>
    </inertial>
    <visual>
      <origin rpy="0 0 0" xyz="0 0 0"/>
      <geometry>
        <mesh filename="package://reemc_description/meshes/hand/hand_finger_3.dae" scale="1 1 -1.0"/>
      </geometry>
      <material name="LightGrey"/>
    </visual>
    <collision>
      <origin rpy="0 0 0" xyz="0 0 0"/>
      <geometry>
        <mesh filename="package://reemc_description/meshes/hand/hand_finger_3_collision.stl" scale="1 1 -1.0"/>
      </geometry>
    </collision>
  </link>
  <gazebo reference="hand_right_index_link">
    <mu1>0.9</mu1>
    <mu2>0.9</mu2>
  </gazebo>
  <gazebo reference="hand_right_index_1_link">
    <kp>1000000.0</kp>
    <kd>100.0</kd>
    <mu1>1.0</mu1>
    <mu2>1.0</mu2>
    <fdir1>0 0 1</fdir1>
    <maxVel>1.0</maxVel>
    <minDepth>0.00</minDepth>
  </gazebo>
  <gazebo reference="hand_right_index_2_link">
    <kp>1000000.0</kp>
    <kd>100.0</kd>
    <mu1>1.0</mu1>
    <mu2>1.0</mu2>
    <fdir1>0 0 1</fdir1>
    <maxVel>1.0</maxVel>
    <minDepth>0.00</minDepth>
  </gazebo>
  <gazebo reference="hand_right_index_3_link">
    <kp>1000000.0</kp>
    <kd>100.0</kd>
    <mu1>1.0</mu1>
    <mu2>1.0</mu2>
    <fdir1>0 0 1</fdir1>
    <maxVel>1.0</maxVel>
    <minDepth>0.00</minDepth>
  </gazebo>
  <gazebo reference="hand_right_index_joint">
    <implicitSpringDamper>1</implicitSpringDamper>
    <provideFeedback>1</provideFeedback>
  </gazebo>
  <gazebo reference="hand_right_index_1_joint">
    <implicitSpringDamper>1</implicitSpringDamper>
    <provideFeedback>1</provideFeedback>
  </gazebo>
  <gazebo reference="hand_right_index_2_joint">
    <implicitSpringDamper>1</implicitSpringDamper>
    <provideFeedback>1</provideFeedback>
  </gazebo>
  <gazebo reference="hand_right_index_3_joint">
    <implicitSpringDamper>1</implicitSpringDamper>
    <provideFeedback>1</provideFeedback>
  </gazebo>
  <gazebo>
    <plugin filename="libgazebo_pal_hand.so" name="gazebo_pal_right_hand_index">
      <actuatedJoint>hand_right_index_joint</actuatedJoint>
      <fingerJoint1>hand_right_index_1_joint</fingerJoint1>
      <fingerJoint2>hand_right_index_2_joint</fingerJoint2>
      <fingerJoint3>hand_right_index_3_joint</fingerJoint3>
    </plugin>
  </gazebo>
  <!-- Actuator -->
  <transmission name="hand_right_index_trans">
    <type>transmission_interface/SimpleTransmission</type>
    <actuator name="hand_right_index_motor">
      <mechanicalReduction>1</mechanicalReduction>
    </actuator>
    <joint name="hand_right_index_joint">
      <hardwareInterface>hardware_interface/PositionJointInterface</hardwareInterface>
    </joint>
  </transmission>
  <!-- Read-only finger phalanxes -->
  <transmission name="hand_right_index_1_trans">
    <type>transmission_interface/SimpleTransmission</type>
    <actuator name="hand_right_index_1_motor">
      <mechanicalReduction>1.0</mechanicalReduction>
    </actuator>
    <joint name="hand_right_index_1_joint">
      <hardwareInterface>hardware_interface/JointStateInterface</hardwareInterface>
    </joint>
  </transmission>
  <transmission name="hand_right_index_2_trans">
    <type>transmission_interface/SimpleTransmission</type>
    <actuator name="hand_right_index_2_motor">
      <mechanicalReduction>1.0</mechanicalReduction>
    </actuator>
    <joint name="hand_right_index_2_joint">
      <hardwareInterface>hardware_interface/JointStateInterface</hardwareInterface>
    </joint>
  </transmission>
  <transmission name="hand_right_index_3_trans">
    <type>transmission_interface/SimpleTransmission</type>
    <actuator name="hand_right_index_3_motor">
      <mechanicalReduction>1.0</mechanicalReduction>
    </actuator>
    <joint name="hand_right_index_3_joint">
      <hardwareInterface>hardware_interface/JointStateInterface</hardwareInterface>
    </joint>
  </transmission>
  <!-- Middle finger -->
  <!-- Actuated joint -->
  <joint name="hand_right_middle_joint" type="revolute">
    <parent link="hand_right_palm_link"/>
    <child link="hand_right_middle_link"/>
    <origin rpy="0.0 0 1.57079632679" xyz="0.101 0.0025 -0.0165"/>
    <axis xyz="0 0 1"/>
    <limit effort="2.0" lower="0.0" upper="4.36332312999" velocity="2.0"/>
    <!-- TODO: Tune values -->
    <dynamics damping="0.5" friction="0.0"/>
    <safety_controller k_position="20" k_velocity="20" soft_lower_limit="0.0" soft_upper_limit="4.34332312999"/>
  </joint>
  <link name="hand_right_middle_link">
    <inertial>
      <origin rpy="0 0 0" xyz="0.00175 -0.01837 -0.00198"/>
      <mass value="0.055"/>
      <inertia ixx="0.00001450121" ixy="-0.00000065488" ixz="-0.00000039654" iyy="0.0000072995" iyz="0.00000012168" izz="0.00001262409"/>
    </inertial>
    <visual>
      <origin rpy="0 0 0" xyz="0 0 0"/>
      <geometry>
        <sphere radius="0.001"/>
      </geometry>
      <material name="LightGrey"/>
    </visual>
    <collision>
      <origin rpy="0 0 0" xyz="0 0 0"/>
      <geometry>
        <sphere radius="0.001"/>
      </geometry>
    </collision>
  </link>
  <!-- Read-only phalanxes-->
  <joint name="hand_right_middle_1_joint" type="revolute">
    <parent link="hand_right_palm_link"/>
    <child link="hand_right_middle_1_link"/>
    <origin rpy="0.0 0 1.57079632679" xyz="0.101 0.0025 -0.0165"/>
    <axis xyz="0 0 1"/>
    <limit effort="2.0" lower="0.0" upper="1.57079632679" velocity="2.0"/>
    <dynamics damping="0.5" friction="0.0"/>
    <mimic joint="hand_right_middle_joint" multiplier="0.36" offset="0.0"/>
  </joint>
  <link name="hand_right_middle_1_link">
    <inertial>
      <origin rpy="0 0 0" xyz="0.00175 -0.01837 -0.00198"/>
      <mass value="0.055"/>
      <inertia ixx="0.00001450121" ixy="-0.00000065488" ixz="-0.00000039654" iyy="0.0000072995" iyz="0.00000012168" izz="0.00001262409"/>
    </inertial>
    <visual>
      <origin rpy="0 0 0" xyz="0 0 0"/>
      <geometry>
        <mesh filename="package://reemc_description/meshes/hand/hand_finger_1.dae" scale="1 1 1.0"/>
      </geometry>
      <material name="LightGrey"/>
    </visual>
    <collision>
      <origin rpy="0 0 0" xyz="0 0 0"/>
      <geometry>
        <mesh filename="package://reemc_description/meshes/hand/hand_finger_1_collision.stl" scale="1 1 1.0"/>
      </geometry>
    </collision>
  </link>
  <joint name="hand_right_middle_2_joint" type="revolute">
    <parent link="hand_right_middle_1_link"/>
    <child link="hand_right_middle_2_link"/>
    <origin rpy="0 0 0" xyz="0.00357 -0.04084 0"/>
    <axis xyz="0 0 1"/>
    <limit effort="1.0" lower="0.0" upper="1.3962634016" velocity="2.0"/>
    <dynamics damping="0.5" friction="0.0"/>
    <mimic joint="hand_right_middle_joint" multiplier="0.32" offset="0.0"/>
  </joint>
  <link name="hand_right_middle_2_link">
    <inertial>
      <origin rpy="0 0 0" xyz="0.00181 -0.01275 -0.00064"/>
      <mass value="0.02972"/>
      <inertia ixx="0.00000428193" ixy="-0.00000049978" ixz="-0.00000002985" iyy="0.00000254434" iyz="0.00000007762" izz="0.00000345152"/>
    </inertial>
    <visual>
      <origin rpy="0 0 0" xyz="0 0 0"/>
      <geometry>
        <mesh filename="package://reemc_description/meshes/hand/hand_finger_2.dae" scale="1 1 1.0"/>
      </geometry>
      <material name="LightGrey"/>
    </visual>
    <collision>
      <origin rpy="0 0 0" xyz="0 0 0"/>
      <geometry>
        <mesh filename="package://reemc_description/meshes/hand/hand_finger_2_collision.stl" scale="1 1 1.0"/>
      </geometry>
    </collision>
  </link>
  <joint name="hand_right_middle_3_joint" type="revolute">
    <parent link="hand_right_middle_2_link"/>
    <child link="hand_right_middle_3_link"/>
    <origin rpy="0 0 0" xyz="0.00572 -0.0269 0"/>
    <axis xyz="0 0 1"/>
    <limit effort="1.0" lower="0.0" upper="1.3962634016" velocity="2.0"/>
    <dynamics damping="0.5" friction="0.0"/>
    <mimic joint="hand_right_middle_joint" multiplier="0.32" offset="0.0"/>
  </joint>
  <link name="hand_right_middle_3_link">
    <inertial>
      <origin rpy="0 0 0" xyz="0 -0.00704 0.00019"/>
      <mass value="0.01522"/>
      <inertia ixx="0.00000128478" ixy="-0.00000008056" ixz="-0.00000001698" iyy="0.00000080139" iyz="-0.00000002884" izz="0.00000090928"/>
    </inertial>
    <visual>
      <origin rpy="0 0 0" xyz="0 0 0"/>
      <geometry>
        <mesh filename="package://reemc_description/meshes/hand/hand_finger_3.dae" scale="1 1 1.0"/>
      </geometry>
      <material name="LightGrey"/>
    </visual>
    <collision>
      <origin rpy="0 0 0" xyz="0 0 0"/>
      <geometry>
        <mesh filename="package://reemc_description/meshes/hand/hand_finger_3_collision.stl" scale="1 1 1.0"/>
      </geometry>
    </collision>
  </link>
  <gazebo reference="hand_right_middle_link">
    <mu1>0.9</mu1>
    <mu2>0.9</mu2>
  </gazebo>
  <gazebo reference="hand_right_middle_1_link">
    <kp>1000000.0</kp>
    <kd>100.0</kd>
    <mu1>1.0</mu1>
    <mu2>1.0</mu2>
    <fdir1>0 0 1</fdir1>
    <maxVel>1.0</maxVel>
    <minDepth>0.00</minDepth>
  </gazebo>
  <gazebo reference="hand_right_middle_2_link">
    <kp>1000000.0</kp>
    <kd>100.0</kd>
    <mu1>1.0</mu1>
    <mu2>1.0</mu2>
    <fdir1>0 0 1</fdir1>
    <maxVel>1.0</maxVel>
    <minDepth>0.00</minDepth>
  </gazebo>
  <gazebo reference="hand_right_middle_3_link">
    <kp>1000000.0</kp>
    <kd>100.0</kd>
    <mu1>1.0</mu1>
    <mu2>1.0</mu2>
    <fdir1>0 0 1</fdir1>
    <maxVel>1.0</maxVel>
    <minDepth>0.00</minDepth>
  </gazebo>
  <gazebo reference="hand_right_middle_joint">
    <implicitSpringDamper>1</implicitSpringDamper>
    <provideFeedback>1</provideFeedback>
  </gazebo>
  <gazebo reference="hand_right_middle_1_joint">
    <implicitSpringDamper>1</implicitSpringDamper>
    <provideFeedback>1</provideFeedback>
  </gazebo>
  <gazebo reference="hand_right_middle_2_joint">
    <implicitSpringDamper>1</implicitSpringDamper>
    <provideFeedback>1</provideFeedback>
  </gazebo>
  <gazebo reference="hand_right_middle_3_joint">
    <implicitSpringDamper>1</implicitSpringDamper>
    <provideFeedback>1</provideFeedback>
  </gazebo>
  <gazebo>
    <plugin filename="libgazebo_pal_hand.so" name="gazebo_pal_right_hand_index">
      <actuatedJoint>hand_right_middle_joint</actuatedJoint>
      <fingerJoint1>hand_right_middle_1_joint</fingerJoint1>
      <fingerJoint2>hand_right_middle_2_joint</fingerJoint2>
      <fingerJoint3>hand_right_middle_3_joint</fingerJoint3>
    </plugin>
  </gazebo>
  <!-- Actuator -->
  <transmission name="hand_right_middle_trans">
    <type>transmission_interface/SimpleTransmission</type>
    <actuator name="hand_right_middle_motor">
      <mechanicalReduction>1</mechanicalReduction>
    </actuator>
    <joint name="hand_right_middle_joint">
      <hardwareInterface>hardware_interface/PositionJointInterface</hardwareInterface>
    </joint>
  </transmission>
  <!-- Read-only finger phalanxes -->
  <transmission name="hand_right_middle_1_trans">
    <type>transmission_interface/SimpleTransmission</type>
    <actuator name="hand_right_middle_1_motor">
      <mechanicalReduction>1.0</mechanicalReduction>
    </actuator>
    <joint name="hand_right_middle_1_joint">
      <hardwareInterface>hardware_interface/JointStateInterface</hardwareInterface>
    </joint>
  </transmission>
  <transmission name="hand_right_middle_2_trans">
    <type>transmission_interface/SimpleTransmission</type>
    <actuator name="hand_right_middle_2_motor">
      <mechanicalReduction>1.0</mechanicalReduction>
    </actuator>
    <joint name="hand_right_middle_2_joint">
      <hardwareInterface>hardware_interface/JointStateInterface</hardwareInterface>
    </joint>
  </transmission>
  <transmission name="hand_right_middle_3_trans">
    <type>transmission_interface/SimpleTransmission</type>
    <actuator name="hand_right_middle_3_motor">
      <mechanicalReduction>1.0</mechanicalReduction>
    </actuator>
    <joint name="hand_right_middle_3_joint">
      <hardwareInterface>hardware_interface/JointStateInterface</hardwareInterface>
    </joint>
  </transmission>
  <!-- grasping hack -->
  <gazebo>
    <gripper name="right_grasp_hack">
      <!--<grasp_check attach_steps="20" detach_steps="40" min_contact_count="2" />-->
      <grasp_check>
        <attach_steps>20</attach_steps>
        <detach_steps>20</detach_steps>
        <min_contact_count>20</min_contact_count>
      </grasp_check>
      <gripper_link>hand_right_middle_1_link</gripper_link>
      <gripper_link>hand_right_index_1_link</gripper_link>
      <gripper_link>hand_right_middle_2_link</gripper_link>
      <gripper_link>hand_right_index_2_link</gripper_link>
      <gripper_link>hand_right_middle_3_link</gripper_link>
      <gripper_link>hand_right_index_3_link</gripper_link>
      <palm_link>hand_right_thumb_link</palm_link>
    </gripper>
  </gazebo>
  <!-- Palm -->
  <joint name="hand_left_palm_joint" type="fixed">
    <parent link="arm_left_tool_link"/>
    <child link="hand_left_palm_link"/>
    <origin rpy="0 0 0" xyz="0 0 0"/>
  </joint>
  <link name="hand_left_palm_link">
    <inertial>
      <origin rpy="0 0 0" xyz="0.05904 0.00925 -0.00075 "/>
      <!--TODO: This does not make sense!, there must be a bug in how Gazebo bungles the CoM of a chain of fixed joints-->
      <mass value="0.68275"/>
      <inertia ixx="0.00045643484" ixy="0.00001885321" ixz="-0.0000103596" iyy="0.00076077407" iyz="-0.00000266311" izz="0.00052521525"/>
    </inertial>
    <visual>
      <origin rpy="0 0 0" xyz="0 0 0"/>
      <geometry>
        <mesh filename="package://reemc_description/meshes/hand/hand_palm.dae" scale="1 1.0 1"/>
      </geometry>
      <material name="LightGrey"/>
    </visual>
    <collision>
      <origin rpy="0 0 0" xyz="0 0 0"/>
      <geometry>
        <mesh filename="package://reemc_description/meshes/hand/hand_palm_collision.stl" scale="1 1.0 1"/>
      </geometry>
    </collision>
  </link>
  <gazebo reference="hand_left_palm_link">
    <kp>1000000.0</kp>
    <kd>100.0</kd>
    <mu1>1.0</mu1>
    <mu2>1.0</mu2>
    <fdir1>0 0 1</fdir1>
    <maxVel>1.0</maxVel>
    <minDepth>0.00</minDepth>
  </gazebo>
  <xacro:hand_gazebo name="hand_left_palm"/>
  <!-- Thumb -->
  <joint name="hand_left_thumb_joint" type="revolute">
    <parent link="hand_left_palm_link"/>
    <child link="hand_left_thumb_link"/>
    <origin rpy="0.0 1.79768912955 -0.226892802759" xyz="0.03649 -0.008  0.02"/>
    <axis xyz="0 0 1"/>
    <limit effort="2.0" lower="0.0" upper="1.57079632679" velocity="2.0"/>
    <dynamics damping="0.5" friction="0.0"/>
    <safety_controller k_position="20" k_velocity="20" soft_lower_limit="0.0" soft_upper_limit="1.55079632679"/>
  </joint>
  <link name="hand_left_thumb_link">
    <inertial>
      <origin rpy="0 0 0" xyz="0.00049 0.00451 0.04179"/>
      <mass value="0.07088"/>
      <inertia ixx="0.0000699364" ixy="0.00000345915" ixz="0.00000425008" iyy="0.00002675459" iyz="0.00002381865" izz="0.00004787167"/>
    </inertial>
    <visual>
      <origin rpy="0 0 0" xyz="0 0 0"/>
      <geometry>
        <mesh filename="package://reemc_description/meshes/hand/hand_thumb.dae" scale="1 1 1.0"/>
      </geometry>
      <material name="LightGrey"/>
    </visual>
    <collision>
      <origin rpy="0 0 0" xyz="0 0 0"/>
      <geometry>
        <mesh filename="package://reemc_description/meshes/hand/hand_thumb_collision.stl" scale="1 1 1.0"/>
      </geometry>
    </collision>
  </link>
  <gazebo reference="hand_left_thumb_link">
    <kp>1000000.0</kp>
    <kd>100.0</kd>
    <mu1>1.0</mu1>
    <mu2>1.0</mu2>
    <fdir1>0 0 1</fdir1>
    <maxVel>1.0</maxVel>
    <minDepth>0.00</minDepth>
  </gazebo>
  <gazebo reference="hand_left_thumb_joint">
    <implicitSpringDamper>1</implicitSpringDamper>
  </gazebo>
  <!-- Grasping frame -->
  <!-- grasp planner will approach along x-axis -->
  <joint name="hand_left_grasping_frame_joint" type="fixed">
    <parent link="hand_left_palm_link"/>
    <child link="hand_left_grasping_frame"/>
    <origin rpy="0 0 0" xyz="0.055 -0.054 0.018"/>
  </joint>
  <link name="hand_left_grasping_frame">
    <inertial>
      <origin rpy="0 0 0" xyz="0 0 0"/>
      <mass value="0.01"/>
      <!-- matrix below must not be zero, or Gazebo won't load -->
      <inertia ixx="0.00001" ixy="0.0" ixz="0.0" iyy="0.00001" iyz="0.0" izz="0.00001"/>
    </inertial>
  </link>
  <transmission name="hand_left_thumb_trans">
    <type>transmission_interface/SimpleTransmission</type>
    <actuator name="hand_left_thumb_motor">
      <mechanicalReduction>1</mechanicalReduction>
    </actuator>
    <joint name="hand_left_thumb_joint">
      <hardwareInterface>hardware_interface/PositionJointInterface</hardwareInterface>
    </joint>
  </transmission>
  <!-- Index finger -->
  <!-- Actuated joint -->
  <joint name="hand_left_index_joint" type="revolute">
    <parent link="hand_left_palm_link"/>
    <child link="hand_left_index_link"/>
    <origin rpy="3.14159265359 0 -1.57079632679" xyz="0.101 -0.0025 0.0165"/>
    <axis xyz="0 0 1"/>
    <limit effort="2.0" lower="0.0" upper="4.36332312999" velocity="2.0"/>
    <!-- TODO: Tune values -->
    <dynamics damping="0.5" friction="0.0"/>
    <safety_controller k_position="20" k_velocity="20" soft_lower_limit="0.0" soft_upper_limit="4.34332312999"/>
  </joint>
  <link name="hand_left_index_link">
    <inertial>
      <origin rpy="0 0 0" xyz="0.00175 -0.01837 -0.00198"/>
      <mass value="0.055"/>
      <inertia ixx="0.00001450121" ixy="-0.00000065488" ixz="-0.00000039654" iyy="0.0000072995" iyz="0.00000012168" izz="0.00001262409"/>
    </inertial>
    <visual>
      <origin rpy="0 0 0" xyz="0 0 0"/>
      <geometry>
        <sphere radius="0.001"/>
      </geometry>
      <material name="LightGrey"/>
    </visual>
    <collision>
      <origin rpy="0 0 0" xyz="0 0 0"/>
      <geometry>
        <sphere radius="0.001"/>
      </geometry>
    </collision>
  </link>
  <!-- Read-only phalanxes-->
  <joint name="hand_left_index_1_joint" type="revolute">
    <parent link="hand_left_palm_link"/>
    <child link="hand_left_index_1_link"/>
    <origin rpy="3.14159265359 0 -1.57079632679" xyz="0.101 -0.0025 0.0165"/>
    <axis xyz="0 0 1"/>
    <limit effort="2.0" lower="0.0" upper="1.57079632679" velocity="2.0"/>
    <dynamics damping="0.5" friction="0.0"/>
    <mimic joint="hand_left_index_joint" multiplier="0.36" offset="0.0"/>
  </joint>
  <link name="hand_left_index_1_link">
    <inertial>
      <origin rpy="0 0 0" xyz="0.00175 -0.01837 -0.00198"/>
      <mass value="0.055"/>
      <inertia ixx="0.00001450121" ixy="-0.00000065488" ixz="-0.00000039654" iyy="0.0000072995" iyz="0.00000012168" izz="0.00001262409"/>
    </inertial>
    <visual>
      <origin rpy="0 0 0" xyz="0 0 0"/>
      <geometry>
        <mesh filename="package://reemc_description/meshes/hand/hand_finger_1.dae" scale="1 1 1.0"/>
      </geometry>
      <material name="LightGrey"/>
    </visual>
    <collision>
      <origin rpy="0 0 0" xyz="0 0 0"/>
      <geometry>
        <mesh filename="package://reemc_description/meshes/hand/hand_finger_1_collision.stl" scale="1 1 1.0"/>
      </geometry>
    </collision>
  </link>
  <joint name="hand_left_index_2_joint" type="revolute">
    <parent link="hand_left_index_1_link"/>
    <child link="hand_left_index_2_link"/>
    <origin rpy="0 0 0" xyz="0.00357 -0.04084 0"/>
    <axis xyz="0 0 1"/>
    <limit effort="1.0" lower="0.0" upper="1.3962634016" velocity="2.0"/>
    <dynamics damping="0.5" friction="0.0"/>
    <mimic joint="hand_left_index_joint" multiplier="0.32" offset="0.0"/>
  </joint>
  <link name="hand_left_index_2_link">
    <inertial>
      <origin rpy="0 0 0" xyz="0.00181 -0.01275 -0.00064"/>
      <mass value="0.02972"/>
      <inertia ixx="0.00000428193" ixy="-0.00000049978" ixz="-0.00000002985" iyy="0.00000254434" iyz="0.00000007762" izz="0.00000345152"/>
    </inertial>
    <visual>
      <origin rpy="0 0 0" xyz="0 0 0"/>
      <geometry>
        <mesh filename="package://reemc_description/meshes/hand/hand_finger_2.dae" scale="1 1 1.0"/>
      </geometry>
      <material name="LightGrey"/>
    </visual>
    <collision>
      <origin rpy="0 0 0" xyz="0 0 0"/>
      <geometry>
        <mesh filename="package://reemc_description/meshes/hand/hand_finger_2_collision.stl" scale="1 1 1.0"/>
      </geometry>
    </collision>
  </link>
  <joint name="hand_left_index_3_joint" type="revolute">
    <parent link="hand_left_index_2_link"/>
    <child link="hand_left_index_3_link"/>
    <origin rpy="0 0 0" xyz="0.00572 -0.0269 0"/>
    <axis xyz="0 0 1"/>
    <limit effort="1.0" lower="0.0" upper="1.3962634016" velocity="2.0"/>
    <dynamics damping="0.5" friction="0.0"/>
    <mimic joint="hand_left_index_joint" multiplier="0.32" offset="0.0"/>
  </joint>
  <link name="hand_left_index_3_link">
    <inertial>
      <origin rpy="0 0 0" xyz="0 -0.00704 0.00019"/>
      <mass value="0.01522"/>
      <inertia ixx="0.00000128478" ixy="-0.00000008056" ixz="-0.00000001698" iyy="0.00000080139" iyz="-0.00000002884" izz="0.00000090928"/>
    </inertial>
    <visual>
      <origin rpy="0 0 0" xyz="0 0 0"/>
      <geometry>
        <mesh filename="package://reemc_description/meshes/hand/hand_finger_3.dae" scale="1 1 1.0"/>
      </geometry>
      <material name="LightGrey"/>
    </visual>
    <collision>
      <origin rpy="0 0 0" xyz="0 0 0"/>
      <geometry>
        <mesh filename="package://reemc_description/meshes/hand/hand_finger_3_collision.stl" scale="1 1 1.0"/>
      </geometry>
    </collision>
  </link>
  <gazebo reference="hand_left_index_link">
    <mu1>0.9</mu1>
    <mu2>0.9</mu2>
  </gazebo>
  <gazebo reference="hand_left_index_1_link">
    <kp>1000000.0</kp>
    <kd>100.0</kd>
    <mu1>1.0</mu1>
    <mu2>1.0</mu2>
    <fdir1>0 0 1</fdir1>
    <maxVel>1.0</maxVel>
    <minDepth>0.00</minDepth>
  </gazebo>
  <gazebo reference="hand_left_index_2_link">
    <kp>1000000.0</kp>
    <kd>100.0</kd>
    <mu1>1.0</mu1>
    <mu2>1.0</mu2>
    <fdir1>0 0 1</fdir1>
    <maxVel>1.0</maxVel>
    <minDepth>0.00</minDepth>
  </gazebo>
  <gazebo reference="hand_left_index_3_link">
    <kp>1000000.0</kp>
    <kd>100.0</kd>
    <mu1>1.0</mu1>
    <mu2>1.0</mu2>
    <fdir1>0 0 1</fdir1>
    <maxVel>1.0</maxVel>
    <minDepth>0.00</minDepth>
  </gazebo>
  <gazebo reference="hand_left_index_joint">
    <implicitSpringDamper>1</implicitSpringDamper>
    <provideFeedback>1</provideFeedback>
  </gazebo>
  <gazebo reference="hand_left_index_1_joint">
    <implicitSpringDamper>1</implicitSpringDamper>
    <provideFeedback>1</provideFeedback>
  </gazebo>
  <gazebo reference="hand_left_index_2_joint">
    <implicitSpringDamper>1</implicitSpringDamper>
    <provideFeedback>1</provideFeedback>
  </gazebo>
  <gazebo reference="hand_left_index_3_joint">
    <implicitSpringDamper>1</implicitSpringDamper>
    <provideFeedback>1</provideFeedback>
  </gazebo>
  <gazebo>
    <plugin filename="libgazebo_pal_hand.so" name="gazebo_pal_right_hand_index">
      <actuatedJoint>hand_left_index_joint</actuatedJoint>
      <fingerJoint1>hand_left_index_1_joint</fingerJoint1>
      <fingerJoint2>hand_left_index_2_joint</fingerJoint2>
      <fingerJoint3>hand_left_index_3_joint</fingerJoint3>
    </plugin>
  </gazebo>
  <!-- Actuator -->
  <transmission name="hand_left_index_trans">
    <type>transmission_interface/SimpleTransmission</type>
    <actuator name="hand_left_index_motor">
      <mechanicalReduction>1</mechanicalReduction>
    </actuator>
    <joint name="hand_left_index_joint">
      <hardwareInterface>hardware_interface/PositionJointInterface</hardwareInterface>
    </joint>
  </transmission>
  <!-- Read-only finger phalanxes -->
  <transmission name="hand_left_index_1_trans">
    <type>transmission_interface/SimpleTransmission</type>
    <actuator name="hand_left_index_1_motor">
      <mechanicalReduction>1.0</mechanicalReduction>
    </actuator>
    <joint name="hand_left_index_1_joint">
      <hardwareInterface>hardware_interface/JointStateInterface</hardwareInterface>
    </joint>
  </transmission>
  <transmission name="hand_left_index_2_trans">
    <type>transmission_interface/SimpleTransmission</type>
    <actuator name="hand_left_index_2_motor">
      <mechanicalReduction>1.0</mechanicalReduction>
    </actuator>
    <joint name="hand_left_index_2_joint">
      <hardwareInterface>hardware_interface/JointStateInterface</hardwareInterface>
    </joint>
  </transmission>
  <transmission name="hand_left_index_3_trans">
    <type>transmission_interface/SimpleTransmission</type>
    <actuator name="hand_left_index_3_motor">
      <mechanicalReduction>1.0</mechanicalReduction>
    </actuator>
    <joint name="hand_left_index_3_joint">
      <hardwareInterface>hardware_interface/JointStateInterface</hardwareInterface>
    </joint>
  </transmission>
  <!-- Middle finger -->
  <!-- Actuated joint -->
  <joint name="hand_left_middle_joint" type="revolute">
    <parent link="hand_left_palm_link"/>
    <child link="hand_left_middle_link"/>
    <origin rpy="3.14159265359 0 -1.57079632679" xyz="0.101 -0.0025 -0.0165"/>
    <axis xyz="0 0 1"/>
    <limit effort="2.0" lower="0.0" upper="4.36332312999" velocity="2.0"/>
    <!-- TODO: Tune values -->
    <dynamics damping="0.5" friction="0.0"/>
    <safety_controller k_position="20" k_velocity="20" soft_lower_limit="0.0" soft_upper_limit="4.34332312999"/>
  </joint>
  <link name="hand_left_middle_link">
    <inertial>
      <origin rpy="0 0 0" xyz="0.00175 -0.01837 -0.00198"/>
      <mass value="0.055"/>
      <inertia ixx="0.00001450121" ixy="-0.00000065488" ixz="-0.00000039654" iyy="0.0000072995" iyz="0.00000012168" izz="0.00001262409"/>
    </inertial>
    <visual>
      <origin rpy="0 0 0" xyz="0 0 0"/>
      <geometry>
        <sphere radius="0.001"/>
      </geometry>
      <material name="LightGrey"/>
    </visual>
    <collision>
      <origin rpy="0 0 0" xyz="0 0 0"/>
      <geometry>
        <sphere radius="0.001"/>
      </geometry>
    </collision>
  </link>
  <!-- Read-only phalanxes-->
  <joint name="hand_left_middle_1_joint" type="revolute">
    <parent link="hand_left_palm_link"/>
    <child link="hand_left_middle_1_link"/>
    <origin rpy="3.14159265359 0 -1.57079632679" xyz="0.101 -0.0025 -0.0165"/>
    <axis xyz="0 0 1"/>
    <limit effort="2.0" lower="0.0" upper="1.57079632679" velocity="2.0"/>
    <dynamics damping="0.5" friction="0.0"/>
    <mimic joint="hand_left_middle_joint" multiplier="0.36" offset="0.0"/>
  </joint>
  <link name="hand_left_middle_1_link">
    <inertial>
      <origin rpy="0 0 0" xyz="0.00175 -0.01837 -0.00198"/>
      <mass value="0.055"/>
      <inertia ixx="0.00001450121" ixy="-0.00000065488" ixz="-0.00000039654" iyy="0.0000072995" iyz="0.00000012168" izz="0.00001262409"/>
    </inertial>
    <visual>
      <origin rpy="0 0 0" xyz="0 0 0"/>
      <geometry>
        <mesh filename="package://reemc_description/meshes/hand/hand_finger_1.dae" scale="1 1 -1.0"/>
      </geometry>
      <material name="LightGrey"/>
    </visual>
    <collision>
      <origin rpy="0 0 0" xyz="0 0 0"/>
      <geometry>
        <mesh filename="package://reemc_description/meshes/hand/hand_finger_1_collision.stl" scale="1 1 -1.0"/>
      </geometry>
    </collision>
  </link>
  <joint name="hand_left_middle_2_joint" type="revolute">
    <parent link="hand_left_middle_1_link"/>
    <child link="hand_left_middle_2_link"/>
    <origin rpy="0 0 0" xyz="0.00357 -0.04084 0"/>
    <axis xyz="0 0 1"/>
    <limit effort="1.0" lower="0.0" upper="1.3962634016" velocity="2.0"/>
    <dynamics damping="0.5" friction="0.0"/>
    <mimic joint="hand_left_middle_joint" multiplier="0.32" offset="0.0"/>
  </joint>
  <link name="hand_left_middle_2_link">
    <inertial>
      <origin rpy="0 0 0" xyz="0.00181 -0.01275 -0.00064"/>
      <mass value="0.02972"/>
      <inertia ixx="0.00000428193" ixy="-0.00000049978" ixz="-0.00000002985" iyy="0.00000254434" iyz="0.00000007762" izz="0.00000345152"/>
    </inertial>
    <visual>
      <origin rpy="0 0 0" xyz="0 0 0"/>
      <geometry>
        <mesh filename="package://reemc_description/meshes/hand/hand_finger_2.dae" scale="1 1 -1.0"/>
      </geometry>
      <material name="LightGrey"/>
    </visual>
    <collision>
      <origin rpy="0 0 0" xyz="0 0 0"/>
      <geometry>
        <mesh filename="package://reemc_description/meshes/hand/hand_finger_2_collision.stl" scale="1 1 -1.0"/>
      </geometry>
    </collision>
  </link>
  <joint name="hand_left_middle_3_joint" type="revolute">
    <parent link="hand_left_middle_2_link"/>
    <child link="hand_left_middle_3_link"/>
    <origin rpy="0 0 0" xyz="0.00572 -0.0269 0"/>
    <axis xyz="0 0 1"/>
    <limit effort="1.0" lower="0.0" upper="1.3962634016" velocity="2.0"/>
    <dynamics damping="0.5" friction="0.0"/>
    <mimic joint="hand_left_middle_joint" multiplier="0.32" offset="0.0"/>
  </joint>
  <link name="hand_left_middle_3_link">
    <inertial>
      <origin rpy="0 0 0" xyz="0 -0.00704 0.00019"/>
      <mass value="0.01522"/>
      <inertia ixx="0.00000128478" ixy="-0.00000008056" ixz="-0.00000001698" iyy="0.00000080139" iyz="-0.00000002884" izz="0.00000090928"/>
    </inertial>
    <visual>
      <origin rpy="0 0 0" xyz="0 0 0"/>
      <geometry>
        <mesh filename="package://reemc_description/meshes/hand/hand_finger_3.dae" scale="1 1 -1.0"/>
      </geometry>
      <material name="LightGrey"/>
    </visual>
    <collision>
      <origin rpy="0 0 0" xyz="0 0 0"/>
      <geometry>
        <mesh filename="package://reemc_description/meshes/hand/hand_finger_3_collision.stl" scale="1 1 -1.0"/>
      </geometry>
    </collision>
  </link>
  <gazebo reference="hand_left_middle_link">
    <mu1>0.9</mu1>
    <mu2>0.9</mu2>
  </gazebo>
  <gazebo reference="hand_left_middle_1_link">
    <kp>1000000.0</kp>
    <kd>100.0</kd>
    <mu1>1.0</mu1>
    <mu2>1.0</mu2>
    <fdir1>0 0 1</fdir1>
    <maxVel>1.0</maxVel>
    <minDepth>0.00</minDepth>
  </gazebo>
  <gazebo reference="hand_left_middle_2_link">
    <kp>1000000.0</kp>
    <kd>100.0</kd>
    <mu1>1.0</mu1>
    <mu2>1.0</mu2>
    <fdir1>0 0 1</fdir1>
    <maxVel>1.0</maxVel>
    <minDepth>0.00</minDepth>
  </gazebo>
  <gazebo reference="hand_left_middle_3_link">
    <kp>1000000.0</kp>
    <kd>100.0</kd>
    <mu1>1.0</mu1>
    <mu2>1.0</mu2>
    <fdir1>0 0 1</fdir1>
    <maxVel>1.0</maxVel>
    <minDepth>0.00</minDepth>
  </gazebo>
  <gazebo reference="hand_left_middle_joint">
    <implicitSpringDamper>1</implicitSpringDamper>
    <provideFeedback>1</provideFeedback>
  </gazebo>
  <gazebo reference="hand_left_middle_1_joint">
    <implicitSpringDamper>1</implicitSpringDamper>
    <provideFeedback>1</provideFeedback>
  </gazebo>
  <gazebo reference="hand_left_middle_2_joint">
    <implicitSpringDamper>1</implicitSpringDamper>
    <provideFeedback>1</provideFeedback>
  </gazebo>
  <gazebo reference="hand_left_middle_3_joint">
    <implicitSpringDamper>1</implicitSpringDamper>
    <provideFeedback>1</provideFeedback>
  </gazebo>
  <gazebo>
    <plugin filename="libgazebo_pal_hand.so" name="gazebo_pal_right_hand_index">
      <actuatedJoint>hand_left_middle_joint</actuatedJoint>
      <fingerJoint1>hand_left_middle_1_joint</fingerJoint1>
      <fingerJoint2>hand_left_middle_2_joint</fingerJoint2>
      <fingerJoint3>hand_left_middle_3_joint</fingerJoint3>
    </plugin>
  </gazebo>
  <!-- Actuator -->
  <transmission name="hand_left_middle_trans">
    <type>transmission_interface/SimpleTransmission</type>
    <actuator name="hand_left_middle_motor">
      <mechanicalReduction>1</mechanicalReduction>
    </actuator>
    <joint name="hand_left_middle_joint">
      <hardwareInterface>hardware_interface/PositionJointInterface</hardwareInterface>
    </joint>
  </transmission>
  <!-- Read-only finger phalanxes -->
  <transmission name="hand_left_middle_1_trans">
    <type>transmission_interface/SimpleTransmission</type>
    <actuator name="hand_left_middle_1_motor">
      <mechanicalReduction>1.0</mechanicalReduction>
    </actuator>
    <joint name="hand_left_middle_1_joint">
      <hardwareInterface>hardware_interface/JointStateInterface</hardwareInterface>
    </joint>
  </transmission>
  <transmission name="hand_left_middle_2_trans">
    <type>transmission_interface/SimpleTransmission</type>
    <actuator name="hand_left_middle_2_motor">
      <mechanicalReduction>1.0</mechanicalReduction>
    </actuator>
    <joint name="hand_left_middle_2_joint">
      <hardwareInterface>hardware_interface/JointStateInterface</hardwareInterface>
    </joint>
  </transmission>
  <transmission name="hand_left_middle_3_trans">
    <type>transmission_interface/SimpleTransmission</type>
    <actuator name="hand_left_middle_3_motor">
      <mechanicalReduction>1.0</mechanicalReduction>
    </actuator>
    <joint name="hand_left_middle_3_joint">
      <hardwareInterface>hardware_interface/JointStateInterface</hardwareInterface>
    </joint>
  </transmission>
  <!-- grasping hack -->
  <gazebo>
    <gripper name="left_grasp_hack">
      <!--<grasp_check attach_steps="20" detach_steps="40" min_contact_count="2" />-->
      <grasp_check>
        <attach_steps>20</attach_steps>
        <detach_steps>20</detach_steps>
        <min_contact_count>20</min_contact_count>
      </grasp_check>
      <gripper_link>hand_left_middle_1_link</gripper_link>
      <gripper_link>hand_left_index_1_link</gripper_link>
      <gripper_link>hand_left_middle_2_link</gripper_link>
      <gripper_link>hand_left_index_2_link</gripper_link>
      <gripper_link>hand_left_middle_3_link</gripper_link>
      <gripper_link>hand_left_index_3_link</gripper_link>
      <palm_link>hand_left_thumb_link</palm_link>
    </gripper>
  </gazebo>
  <!-- stereo camera -->
  <!-- IMPORTANT: focal_length = image_width/(2tan(hfov/2)) -->
  <joint name="stereo_frame_joint" type="fixed">
    <origin rpy="1.56293 -0.00855922 -0.0201307" xyz="0.08203  -0.0935  0.0365"/>
    <parent link="head_2_link"/>
    <child link="stereo_link"/>
  </joint>
  <!-- camera link is at center of the optical frame, but in x-forward, z-upwards and y-leftwards notation (required by gazebo to simulate a camera) -->
  <link name="stereo_link">
    <inertial>
      <mass value="0.01"/>
      <origin rpy="0 0 0" xyz="0 0 0"/>
      <inertia ixx="0" ixy="0" ixz="0" iyy="0" iyz="0" izz="0"/>
      <!-- this inertia is made up for now. -->
    </inertial>
    <visual>
      <origin rpy="0 0 0" xyz="0 0 0"/>
      <geometry>
        <box size="0.001 0.001 0.001"/>
      </geometry>
      <material name="Blue"/>
    </visual>
    <collision>
      <origin rpy="0 0 0" xyz="0 0 0"/>
      <geometry>
        <box size="0.001 0.001 0.001"/>
      </geometry>
    </collision>
  </link>
  <!-- attach optical frame to the camera link -->
  <joint name="stereo_optical_frame_joint" type="fixed">
    <origin rpy="-1.57079632679 0.0 -1.57079632679" xyz="0 0 0"/>
    <!-- rotate frame from x-forward to z-forward camera coords -->
    <parent link="stereo_link"/>
    <child link="stereo_optical_frame"/>
  </joint>
  <!-- optical frame for the stereo camera, with z-forward notation, this is the frame stereo camera images users should refer to -->
  <link name="stereo_optical_frame" type="camera">
    <inertial>
      <mass value="0.01"/>
      <origin rpy="0 0 0" xyz="0 0 0"/>
      <inertia ixx="0" ixy="0" ixz="0" iyy="0" iyz="0" izz="0"/>
      <!-- this inertia is made up for now. -->
    </inertial>
  </link>
  <!-- stereo left camera -->
  <joint name="stereo_gazebo_left_camera_frame_joint" type="fixed">
    <origin rpy="0.0 0.0 0.0" xyz="0 0 0"/>
    <parent link="stereo_link"/>
    <child link="stereo_gazebo_left_camera_link"/>
  </joint>
  <link name="stereo_gazebo_left_camera_link">
    <inertial>
      <mass value="0.1"/>
      <origin xyz="0 0 0"/>
      <inertia ixx="0" ixy="0.0" ixz="0.0" iyy="0" iyz="0.0" izz="0"/>
    </inertial>
    <visual>
      <origin rpy="0 1.57079632679 0" xyz="-0.01 0 0"/>
      <geometry>
        <cylinder length="0.018" radius="0.01"/>
      </geometry>
      <material name="Blue"/>
    </visual>
  </link>
  <!-- stereo right camera -->
  <joint name="stereo_gazebo_right_camera_frame_joint" type="fixed">
    <origin rpy="0.0 0.0 0.0" xyz="0.0 -0.073 0.0"/>
    <parent link="stereo_link"/>
    <child link="stereo_gazebo_right_camera_link"/>
  </joint>
  <link name="stereo_gazebo_right_camera_link">
    <inertial>
      <mass value="0.1"/>
      <origin xyz="0 0 0"/>
      <inertia ixx="0" ixy="0.0" ixz="0.0" iyy="0" iyz="0.0" izz="0"/>
    </inertial>
    <visual>
      <origin rpy="0 1.57079632679 0" xyz="-0.01 0 0"/>
      <geometry>
        <cylinder length="0.018" radius="0.01"/>
      </geometry>
      <material name="Blue"/>
    </visual>
  </link>
  <!-- Stereo camera Gazebo simulation -->
  <gazebo reference="stereo_link">
    <sensor name="gazebo_stereo_camera" type="multicamera">
      <update_rate>25.0</update_rate>
      <camera name="left">
        <horizontal_fov>1.23918376892</horizontal_fov>
        <image>
          <width>659 </width>
          <height> 493</height>
          <format>B8G8R8</format>
        </image>
        <clip>
          <near>0.01</near>
          <far>100</far>
        </clip>
      </camera>
      <camera name="right">
        <pose>0 -0.073 0 0 0 0</pose>
        <!-- the pose is wrt /stereo_link which is the parent of stereo_optical_frame -->
        <horizontal_fov>1.23918376892</horizontal_fov>
        <image>
          <width>659 </width>
          <height> 493</height>
          <format>B8G8R8</format>
        </image>
        <clip>
          <near>0.01</near>
          <far>100</far>
        </clip>
      </camera>
      <plugin filename="libgazebo_ros_multicamera.so" name="stereo_camera_controller">
        <alwaysOn>true</alwaysOn>
        <updateRate>25.0</updateRate>
        <cameraName>stereo</cameraName>
        <imageTopicName>image</imageTopicName>
        <cameraInfoTopicName>camera_info</cameraInfoTopicName>
        <frameName>stereo_optical_frame</frameName>
        <hackBaseline>0.073</hackBaseline>
        <CxPrime>330.0</CxPrime>
        <Cx>330.0</Cx>
        <Cy>247.0</Cy>
        <focalLength>461.943804</focalLength>
        <!-- image_width / (2*tan(hfov_radian /2)) -->
        <distortionK1>0.0</distortionK1>
        <distortionK2>0.0</distortionK2>
        <distortionK3>0.0</distortionK3>
        <distortionT1>0.0</distortionT1>
        <distortionT2>0.0</distortionT2>
      </plugin>
    </sensor>
  </gazebo>
  <joint name="back_camera_frame_joint" type="fixed">
    <origin rpy="-1.57079632679 0 3.14159265359" xyz="-0.128 -0.317 0"/>
    <parent link="torso_2_link"/>
    <child link="back_camera_link"/>
  </joint>
  <!-- camera link is at center of the optical frame, but in x-forward, z-upwards and y-leftwards notation (required by gazebo to simulate a camera) -->
  <link name="back_camera_link">
    <inertial>
      <mass value="0.05"/>
      <origin rpy="0 0 0" xyz="0 0 0"/>
      <inertia ixx="0.01" ixy="0" ixz="0" iyy="0.01" iyz="0" izz="0.01"/>
      <!-- this inertia is made up for now. -->
    </inertial>
    <visual>
      <origin rpy="0 0 0" xyz="0 0 0"/>
      <geometry>
        <box size="0.001 0.001 0.001"/>
      </geometry>
    </visual>
    <collision>
      <origin rpy="0 0 0" xyz="0 0 0"/>
      <geometry>
        <box size="0.001 0.001 0.001"/>
      </geometry>
    </collision>
  </link>
  <!-- attach optical frame to the camera link -->
  <joint name="back_camera_optical_frame_joint" type="fixed">
    <origin rpy="-1.57079632679 0.0 -1.57079632679" xyz="0 0 0"/>
    <!-- rotate frame from x-forward to z-forward camera coords -->
    <parent link="back_camera_link"/>
    <child link="back_camera_optical_frame"/>
  </joint>
  <!-- optical frame for the back camera, with z-forward notation, this is the frame back camera images users should refer to -->
  <link name="back_camera_optical_frame" type="camera">
    <inertial>
      <mass value="0.05"/>
      <inertia ixx="0" ixy="0" ixz="0" iyy="0" iyz="0" izz="0"/>
    </inertial>
  </link>
  <!-- back camera -->
  <joint name="back_camera_gazebo_back_camera_frame_joint" type="fixed">
    <origin rpy="0.0 0.0 0.0" xyz="0 0 0"/>
    <parent link="back_camera_link"/>
    <child link="back_camera_gazebo_back_camera_link"/>
  </joint>
  <link name="back_camera_gazebo_back_camera_link">
    <inertial>
      <mass value="0.1"/>
      <origin xyz="0 0 0"/>
      <inertia ixx="0" ixy="0.0" ixz="0.0" iyy="0" iyz="0.0" izz="0"/>
    </inertial>
    <visual>
      <origin rpy="0 1.57079632679 0" xyz="-0.01 0 0"/>
      <geometry>
        <cylinder length="0.02" radius="0.01"/>
      </geometry>
      <material name="Blue"/>
    </visual>
  </link>
  <!-- Back camera Gazebo simulation -->
  <gazebo reference="back_camera_link">
    <sensor name="gazebo_back_camera_camera" type="camera">
      <update_rate>15.0</update_rate>
      <camera>
        <horizontal_fov>1.57078675232</horizontal_fov>
        <image>
          <width>752 </width>
          <height> 480</height>
          <format>B8G8R8</format>
        </image>
        <clip>
          <near>0.01</near>
          <far>100</far>
        </clip>
      </camera>
      <plugin filename="libgazebo_ros_camera.so" name="monocular_camera_controller">
        <alwaysOn>true</alwaysOn>
        <updateRate>15.0</updateRate>
        <cameraName>back_camera</cameraName>
        <imageTopicName>image</imageTopicName>
        <cameraInfoTopicName>camera_info</cameraInfoTopicName>
        <frameName>back_camera_optical_frame</frameName>
        <hackBaseline>0</hackBaseline>
        <CxPrime>376.5</CxPrime>
        <Cx>376.5</Cx>
        <Cy>240.5</Cy>
        <focalLength>376.002379</focalLength>
        <!-- image_width / (2*tan(hfov_radian /2)) -->
        <distortionK1>0.0</distortionK1>
        <distortionK2>0.0</distortionK2>
        <distortionK3>0.0</distortionK3>
        <distortionT1>0.0</distortionT1>
        <distortionT2>0.0</distortionT2>
      </plugin>
    </sensor>
  </gazebo>
  <!-- imu -->
  <link name="imu_link">
    <inertial>
      <mass value="0.01"/>
      <origin xyz="0 0 0"/>
      <inertia ixx="0.000001" ixy="0" ixz="0" iyy="0.000001" iyz="0" izz="0.000001"/>
    </inertial>
    <visual>
      <origin rpy="0 0 0" xyz="0 0 0"/>
      <geometry>
        <box size="0.01 0.01 0.01"/>
      </geometry>
    </visual>
  </link>
  <joint name="imu_joint" type="fixed">
    <origin rpy="3.14159265359 0 0" xyz="0 0 0"/>
    <parent link="base_link"/>
    <child link="imu_link"/>
  </joint>
</robot>
